Workbook

Sheet abra02
A1: abra02 | C1: G1 = E25 | D1: Only 72 electrodes in 2022, 96 in 2021 | S1: 0 | T1: -61 | V1: 0 | W1: 3854.89 | Y1: =W1-MAX(W:W) -> -28.549 | AB1: =V1 -> 0 | AC1: =Y1 -> -28.549
S2: 4.9 | T2: -60.5 | V2: 4.9 | W2: 3854.882 | Y2: =W2-MAX(W:W) -> -28.557 | AB2: =V2 -> 4.9 | AC2: =Y2 -> -28.557
C3: ERT (original) | E3: RST | H3: RST (new) | S3: 9.8 | T3: -60.1 | V3: 9.8 | W3: 3854.839 | Y3: =W3-MAX(W:W) -> -28.6 | AB3: =V3 -> 9.8 | AC3: =Y3 -> -28.6
A4: #ERT | B4: #GST | C4: x | D4: z | E4: x | F4: z_alt | G4: z_depth | H4: x | I4: z | S4: 14.8 | T4: -59.7 | V4: 14.8 | W4: 3854.818 | Y4: =W4-MAX(W:W) -> -28.621 | AB4: =V4 -> 14.8 | AC4: =Y4 -> -28.621
A5: E1 | C5: 0 | D5: -61 | L5: 0 | M5: 3854.89 | O5: 96 | P5: 0 | S5: 19.7 | T5: -59.2 | V5: 19.7 | W5: 3854.809 | Y5: =W5-MAX(W:W) -> -28.63 | AB5: =V5 -> 19.7 | AC5: =Y5 -> -28.63
A6: E2 | C6: 4.9 | D6: -60.5 | L6: 5 | M6: 3854.882 | O6: 1 | P6: -61 | S6: 24.6 | T6: -58.8 | V6: 24.6 | W6: 3854.817 | Y6: =W6-MAX(W:W) -> -28.622 | AB6: =V6 -> 24.6 | AC6: =Y6 -> -28.622
A7: E3 | C7: 9.8 | D7: -60.1 | L7: 10 | M7: 3854.839 | O7: 2 | P7: -60.5 | S7: 29.5 | T7: -58.4 | V7: 29.5 | W7: 3854.806 | Y7: =W7-MAX(W:W) -> -28.633 | AB7: =V7 -> 29.5 | AC7: =Y7 -> -28.633
A8: E4 | C8: 14.8 | D8: -59.7 | L8: 15 | M8: 3854.818 | O8: 3 | P8: -60.1 | S8: 34.5 | T8: -58.1 | V8: 34.5 | W8: 3854.853 | Y8: =W8-MAX(W:W) -> -28.586 | AB8: =V8 -> 34.5 | AC8: =Y8 -> -28.586
A9: E5 | C9: 19.7 | D9: -59.2 | L9: 20 | M9: 3854.809 | O9: 4 | P9: -59.7 | S9: 39.4 | T9: -57.6 | V9: 39.4 | W9: 3854.856 | Y9: =W9-MAX(W:W) -> -28.583 | AB9: =V9 -> 39.4 | AC9: =Y9 -> -28.583
A10: E6 | C10: 24.6 | D10: -58.8 | L10: 25 | M10: 3854.817 | O10: 5 | P10: -59.2 | S10: 44.3 | T10: -57.1 | V10: 44.3 | W10: 3854.905 | Y10: =W10-MAX(W:W) -> -28.534 | AB10: =V10 -> 44.3 | AC10: =Y10 -> -28.534
A11: E7 | C11: 29.5 | D11: -58.4 | L11: 30 | M11: 3854.806 | O11: 6 | P11: -58.8 | S11: 49.2 | T11: -56.5 | V11: 49.2 | W11: 3854.984 | Y11: =W11-MAX(W:W) -> -28.455 | AB11: =V11 -> 49.2 | AC11: =Y11 -> -28.455
A12: E8 | C12: 34.5 | D12: -58.1 | L12: 35 | M12: 3854.853 | O12: 7 | P12: -58.4 | S12: 54.2 | T12: -55.6 | V12: 54.2 | W12: 3854.996 | Y12: =W12-MAX(W:W) -> -28.443 | AB12: =V12 -> 54.2 | AC12: =Y12 -> -28.443
A13: E9 | C13: 39.4 | D13: -57.6 | L13: 40 | M13: 3854.856 | O13: 8 | P13: -58.1 | S13: 59.2 | T13: -54.5 | V13: 59.2 | W13: 3855.055 | Y13: =W13-MAX(W:W) -> -28.384 | AB13: =V13 -> 59.2 | AC13: =Y13 -> -28.384
A14: E10 | C14: 44.3 | D14: -57.1 | L14: 45 | M14: 3854.905 | O14: 9 | P14: -57.6 | S14: 64 | T14: -53.7 | V14: 64 | W14: 3855.176 | Y14: =W14-MAX(W:W) -> -28.263 | AB14: =V14 -> 64 | AC14: =Y14 -> -28.263
A15: E11 | C15: 49.2 | D15: -56.5 | L15: 50 | M15: 3854.984 | O15: 10 | P15: -57.1 | S15: 68.9 | T15: -52.9 | V15: 68.9 | W15: 3855.193 | Y15: =W15-MAX(W:W) -> -28.246 | AB15: =V15 -> 68.9 | AC15: =Y15 -> -28.246
A16: E12 | C16: 54.2 | D16: -55.6 | L16: 55 | M16: 3854.996 | O16: 11 | P16: -56.5 | S16: 73.8 | T16: -51.9 | V16: 73.8 | W16: 3855.525 | Y16: =W16-MAX(W:W) -> -27.914 | AB16: =V16 -> 73.8 | AC16: =Y16 -> -27.914
... A23: E19 | C23: 88.7 | D23: -50.4 | L23: 90 | M23: 3855.328 | O23: 18 | P23: -50.4 | S23: 108.4 | T23: -50.7 | V23: 108.4 | W23: 3859.652 | Y23: =W23-MAX(W:W) -> -23.787 | AB23: =V23 -> 108.4 | AC23: =Y23 -> -23.787
A24: E20 | C24: 93.6 | D24: -50.3 | L24: 95 | M24: 3856.578 | O24: 19 | P24: -50.4 | S24: 113.4 | T24: -51.2 | V24: 113.4 | W24: 3860.308 | X24: 3860.96 | Y24: =W24-MAX(W:W) -> -23.131 | Z24: =V24 -> 113.4 | AA24: =Y24 -> -23.131 | AB24: =V24 -> 113.4 | AC24: =Y24 -> -23.131
A25: E21 | C25: 98.6 | D25: -50.3 | L25: 100 | M25: 3857.462 | O25: 20 | P25: -50.3 | S25: 118.4 | T25: -51.7 | V25: 118.4 | W25: 3861.019 | X25: 3861.019 | Y25: =W25-MAX(W:W) -> -22.42 | Z25: =V25 -> 118.4 | AA25: =Y25 -> -22.42 | AB25: =V25 -> 118.4 | AC25: =Y25 -> -22.42
A26: E22 | C26: 103.5 | D26: -50.3 | L26: 105 | M26: 3858.524 | O26: 21 | P26: -50.3 | S26: 123.3 | T26: -52.1 | V26: 123.3 | W26: 3861.839 | X26: 3861.839 | Y26: =W26-MAX(W:W) -> -21.6 | Z26: =V26 -> 123.3 | AA26: =Y26 -> -21.6 | AB26: =V26 -> 123.3 | AC26: =Y26 -> -21.6
A27: E23 | C27: 108.4 | D27: -50.7 | L27: 110 | M27: 3859.652 | O27: 22 | P27: -50.3 | S27: 128.2 | T27: -52.4 | V27: 128.2 | W27: 3861.73 | X27: 3861.73 | Y27: =W27-MAX(W:W) -> -21.709 | Z27: =V27 -> 128.2 | AA27: =Y27 -> -21.709 | AB27: =V27 -> 128.2 | AC27: =Y27 -> -21.709
A28: E24 | B28: offset | C28: 113.4 | D28: -51.2 | E28: -7.5 | F28: 3860.96 | G28: =F28-MAX(F:F) -> -22.027 | H28: =C28 -> 113.4 | I28: =D28 -> -51.2 | J28: -7.5 | K28: -22.03 | L28: 115 | M28: 3860.308 | O28: 23 | P28: -50.7 | S28: 133.2 | T28: -52.7 | V28: 133.2 | W28: 3862.493 | X28: 3862.493 | Y28: =W28-MAX(W:W) -> -20.946 | Z28: =V28 -> 133.2 | AA28: =Y28 -> -20.946 | AB28: =V28 -> 133.2 | AC28: =Y28 -> -20.946
A29: E25 | B29: G1 | C29: 118.4 | D29: -51.7 | E29: 0 | F29: 3861.019 | G29: =F29-MAX(F:F) -> -21.968 | H29: =C29 -> 118.4 | I29: =D29 -> -51.7 | J29: -3.75 | K29: -22 | L29: 120 | M29: 3861.019 | O29: 24 | P29: -51.2 | S29: 138.2 | T29: -53 | V29: 138.2 | W29: 3863.137 | X29: 3863.137 | Y29: =W29-MAX(W:W) -> -20.302 | Z29: =V29 -> 138.2 | AA29: =Y29 -> -20.302 | AB29: =V29 -> 138.2 | AC29: =Y29 -> -20.302
A30: E26 | B30: G2 | C30: 123.3 | D30: -52.1 | E30: 4.9 | F30: 3861.839 | G30: =F30-MAX(F:F) -> -21.148 | H30: =C30 -> 123.3 | I30: =D30 -> -52.1 | J30: 0 | K30: -21.97 | L30: 125 | M30: 3861.839 | O30: 25 | P30: -51.7 | S30: 143.2 | T30: -53.2 | V30: 143.2 | W30: 3863.678 | X30: 3863.678 | Y30: =W30-MAX(W:W) -> -19.761 | Z30: =V30 -> 143.2 | AA30: =Y30 -> -19.761 | AB30: =V30 -> 143.2 | AC30: =Y30 -> -19.761
A31: E27 | B31: G3 | C31: 128.2 | D31: -52.4 | E31: 9.9 | F31: 3861.73 | G31: =F31-MAX(F:F) -> -21.257 | H31: =C31 -> 128.2 | I31: =D31 -> -52.4 | J31: 2.45 | K31: -21.56 | L31: 130 | M31: 3861.73 | O31: 26 | P31: -52.1 | S31: 148.2 | T31: -53.5 | V31: 148.2 | W31: 3863.512 | X31: 3863.512 | Y31: =W31-MAX(W:W) -> -19.927 | Z31: =V31 -> 148.2 | AA31: =Y31 -> -19.927 | AB31: =V31 -> 148.2 | AC31: =Y31 -> -19.927
A32: E28 | B32: G4 | C32: 133.2 | D32: -52.7 | E32: 14.9 | F32: 3862.493 | G32: =F32-MAX(F:F) -> -20.494 | H32: =C32 -> 133.2 | I32: =D32 -> -52.7 | J32: 4.9 | K32: -21.15 | L32: 135 | M32: 3862.493 | O32: 27 | P32: -52.4 | S32: 153.2 | T32: -53.8 | V32: 153.2 | W32: 3862.611 | X32: 3862.611 | Y32: =W32-MAX(W:W) -> -20.828 | Z32: =V32 -> 153.2 | AA32: =Y32 -> -20.828 | AB32: =V32 -> 153.2 | AC32: =Y32 -> -20.828
A33: E29 | B33: G5 | C33: 138.2 | D33: -53 | E33: 19.8 | F33: 3863.137 | G33: =F33-MAX(F:F) -> -19.85 | H33: =C33 -> 138.2 | I33: =D33 -> -53 | J33: 7.4 | K33: -21.21 | L33: 140 | M33: 3863.137 | O33: 28 | P33: -52.7 | S33: 158.1 | T33: -54 | V33: 158.1 | W33: 3862.605 | X33: 3862.605 | Y33: =W33-MAX(W:W) -> -20.834 | Z33: =V33 -> 158.1 | AA33: =Y33 -> -20.834 | AB33: =V33 -> 158.1 | AC33: =Y33 -> -20.834
A34: E30 | B34: G6 | C34: 143.2 | D34: -53.2 | E34: 24.8 | F34: 3863.678 | G34: =F34-MAX(F:F) -> -19.309 | H34: =C34 -> 143.2 | I34: =D34 -> -53.2 | J34: 9.9 | K34: -21.26 | L34: 145 | M34: 3863.678 | O34: 29 | P34: -53 | S34: 162.9 | T34: -54.1 | V34: 162.9 | W34: 3861.233 | X34: 3861.233 | Y34: =W34-MAX(W:W) -> -22.206 | Z34: =V34 -> 162.9 | AA34: =Y34 -> -22.206 | AB34: =V34 -> 162.9 | AC34: =Y34 -> -22.206
A35: E31 | B35: G7 | C35: 148.2 | D35: -53.5 | E35: 29.8 | F35: 3863.512 | G35: =F35-MAX(F:F) -> -19.475 | H35: =C35 -> 148.2 | I35: =D35 -> -53.5 | J35: 12.4 | K35: -20.88 | L35: 150 | M35: 3863.512 | O35: 30 | P35: -53.2 | S35: 167.9 | T35: -54.2 | V35: 167.9 | W35: 3859.786 | X35: 3859.786 | Y35: =W35-MAX(W:W) -> -23.653 | Z35: =V35 -> 167.9 | AA35: =Y35 -> -23.653 | AB35: =V35 -> 167.9 | AC35: =Y35 -> -23.653
A36: E32 | B36: G8 | C36: 153.2 | D36: -53.8 | E36: 34.7 | F36: 3862.611 | G36: =F36-MAX(F:F) -> -20.376 | H36: =C36 -> 153.2 | I36: =D36 -> -53.8 | J36: 14.9 | K36: -20.5 | L36: 155 | M36: 3862.611 | O36: 31 | P36: -53.5 | S36: 172.8 | T36: -54.2 | V36: 172.8 | W36: 3859.329 | X36: 3859.329 | Y36: =W36-MAX(W:W) -> -24.11 | Z36: =V36 -> 172.8 | AA36: =Y36 -> -24.11 | AB36: =V36 -> 172.8 | AC36: =Y36 -> -24.11
A37: E33 | B37: G9 | C37: 158.1 | D37: -54 | E37: 39.7 | F37: 3862.605 | G37: =F37-MAX(F:F) -> -20.382 | H37: =C37 -> 158.1 | I37: =D37 -> -54 | J37: 17.35 | K37: -20.17 | L37: 160 | M37: 3862.605 | O37: 32 | P37: -53.8 | S37: 177.7 | T37: -54.2 | V37: 177.7 | W37: 3859.2 | X37: 3859.2 | Y37: =W37-MAX(W:W) -> -24.239 | Z37: =V37 -> 177.7 | AA37: =Y37 -> -24.239 | AB37: =V37 -> 177.7 | AC37: =Y37 -> -24.239
A38: E34 | B38: G10 | C38: 162.9 | D38: -54.1 | E38: 44.5 | F38: 3861.233 | G38: =F38-MAX(F:F) -> -21.754 | H38: =C38 -> 162.9 | I38: =D38 -> -54.1 | J38: 19.8 | K38: -19.85 | L38: 165 | M38: 3861.233 | O38: 33 | P38: -54 | S38: 182.6 | T38: -54.2 | V38: 182.6 | W38: 3859.388 | X38: 3859.388 | Y38: =W38-MAX(W:W) -> -24.051 | Z38: =V38 -> 182.6 | AA38: =Y38 -> -24.051 | AB38: =V38 -> 182.6 | AC38: =Y38 -> -24.051
A39: E35 | B39: G11 | C39: 167.9 | D39: -54.2 | E39: 49.3 | F39: 3859.786 | G39: =F39-MAX(F:F) -> -23.201 | H39: =C39 -> 167.9 | I39: =D39 -> -54.2 | J39: 22.3 | K39: -19.58 | L39: 170 | M39: 3859.786 | O39: 34 | P39: -54.1 | S39: 187.6 | T39: -54.2 | V39: 187.6 | W39: 3860.005 | X39: 3860.005 | Y39: =W39-MAX(W:W) -> -23.434 | Z39: =V39 -> 187.6 | AA39: =Y39 -> -23.434 | AB39: =V39 -> 187.6 | AC39: =Y39 -> -23.434
... A67: E63 | B67: G39 | C67: 302.3 | D67: -23.1 | E67: 186.4 | F67: 3881.782 | G67: =F67-MAX(F:F) -> -1.205 | H67: =C67 -> 302.3 | I67: =D67 -> -23.1 | J67: 90.65 | K67: -16.77 | L67: 330 | M67: 3882.744 | O67: 62 | P67: -23.6 | S67: 322.3 | T67: -20.3 | V67: 322.3 | W67: 3883.273 | X67: 3882.987 | Y67: =W67-MAX(W:W) -> -0.166 | Z67: =V67 -> 322.3 | AA67: =Y67 -> -0.166 | AB67: =V67 -> 322.3 | AC67: =Y67 -> -0.166
A68: E64 | B68: G40 | C68: 307.3 | D68: -21.7 | E68: 191.4 | F68: 3882.063 | G68: =F68-MAX(F:F) -> -0.924 | H68: =C68 -> 307.3 | I68: =D68 -> -21.7 | J68: 93 | K68: -15.92 | L68: 335 | M68: 3882.933 | O68: 63 | P68: -23.1 | S68: 327.3 | T68: -20.3 | V68: 327.3 | W68: 3883.225 | Y68: =W68-MAX(W:W) -> -0.214 | AB68: =V68 -> 327.3 | AC68: =Y68 -> -0.214
A69: E65 | B69: G41 | C69: 312.3 | D69: -20.6 | E69: 196.4 | F69: 3882.744 | G69: =F69-MAX(F:F) -> -0.243 | H69: =C69 -> 312.3 | I69: =D69 -> -20.6 | J69: 95.35 | K69: -15.07 | L69: 340 | M69: 3883.195 | O69: 64 | P69: -21.7 | S69: 332.2 | T69: -20 | V69: 332.2 | W69: 3883.439 | Y69: =W69-MAX(W:W) -> 0 | AB69: =V69 -> 332.2 | AC69: =Y69 -> 0
A70: E66 | B70: G42 | C70: 317.3 | D70: -20.8 | E70: 201.4 | F70: 3882.933 | G70: =F70-MAX(F:F) -> -0.054 | H70: =C70 -> 317.3 | I70: =D70 -> -20.8 | J70: 97.7 | K70: -14.22 | L70: 345 | M70: 3883.43 | O70: 65 | P70: -20.6 | S70: 337.2 | T70: -19.8 | V70: 337.2 | W70: 3883.2 | Y70: =W70-MAX(W:W) -> -0.239 | AB70: =V70 -> 337.2 | AC70: =Y70 -> -0.239
A71: E67 | B71: G43 | C71: 322.3 | D71: -20.3 | E71: 212.5 | F71: 3882.987 | G71: =F71-MAX(F:F) -> 0 | H71: =C71 -> 322.3 | I71: =D71 -> -20.3 | J71: 100.05 | K71: -13.38 | L71: 350 | M71: 3883.273 | O71: 66 | P71: -20.8 | S71: 342.2 | T71: -19.1 | V71: 342.2 | W71: 3882.701 | Y71: =W71-MAX(W:W) -> -0.738 | AB71: =V71 -> 342.2 | AC71: =Y71 -> -0.738
A72: E68 | B72: G44 | C72: 327.3 | D72: -20.3 | J72: 102.4 | K72: -12.54 | L72: 355 | M72: 3883.225 | O72: 67 | P72: -20.3 | S72: 347.2 | T72: -18.4 | V72: 347.2 | W72: 3882.802 | Y72: =W72-MAX(W:W) -> -0.637 | AB72: =V72 -> 347.2 | AC72: =Y72 -> -0.637
A73: E69 | B73: G45 | C73: 332.2 | D73: -20 | J73: 104.75 | K73: -11.74 | L73: 360 | M73: 3883.439 | O73: 68 | P73: -20.3 | S73: 352.2 | T73: -18.2 | V73: 352.2 | AC73: =Y73 -> 0
...

Sheet abra02_new
A1: abra02 | B1: ERT | H1: RST
A2: G1 = E25
B4: x | C4: z | D4: x | E4: z depth | F4: x true | G4: zdepth | H4: geophone
A5: E1 | B5: 0 | C5: 3854.89 | D5: =B5 -> 0 | E5: =C5-MAX($C$5:$C$76) -> -28.549 | F5: 0 | G5: -28.549
A6: E2 | B6: 5 | C6: 3854.882 | D6: =B6 -> 5 | E6: =C6-MAX($C$5:$C$76) -> -28.557 | F6: 4.9 | G6: -28.557
A7: E3 | B7: 10 | C7: 3854.839 | D7: =B7 -> 10 | E7: =C7-MAX($C$5:$C$76) -> -28.6 | F7: 9.8 | G7: -28.6
A8: E4 | B8: 15 | C8: 3854.818 | D8: =B8 -> 15 | E8: =C8-MAX($C$5:$C$76) -> -28.621 | F8: 14.8 | G8: -28.621
A9: E5 | B9: 20 | C9: 3854.809 | D9: =B9 -> 20 | E9: =C9-MAX($C$5:$C$76) -> -28.63 | F9: 19.7 | G9: -28.63
A10: E6 | B10: 25 | C10: 3854.817 | D10: =B10 -> 25 | E10: =C10-MAX($C$5:$C$76) -> -28.622 | F10: 24.6 | G10: -28.622
A11: E7 | B11: 30 | C11: 3854.806 | D11: =B11 -> 30 | E11: =C11-MAX($C$5:$C$76) -> -28.633 | F11: 29.5 | G11: -28.633
A12: E8 | B12: 35 | C12: 3854.853 | D12: =B12 -> 35 | E12: =C12-MAX($C$5:$C$76) -> -28.586 | F12: 34.5 | G12: -28.586
A13: E9 | B13: 40 | C13: 3854.856 | D13: =B13 -> 40 | E13: =C13-MAX($C$5:$C$76) -> -28.583 | F13: 39.4 | G13: -28.583
A14: E10 | B14: 45 | C14: 3854.905 | D14: =B14 -> 45 | E14: =C14-MAX($C$5:$C$76) -> -28.534 | F14: 44.3 | G14: -28.534
A15: E11 | B15: 50 | C15: 3854.984 | D15: =B15 -> 50 | E15: =C15-MAX($C$5:$C$76) -> -28.455 | F15: 49.2 | G15: -28.455
A16: E12 | B16: 55 | C16: 3854.996 | D16: =B16 -> 55 | E16: =C16-MAX($C$5:$C$76) -> -28.443 | F16: 54.2 | G16: -28.443
... A27: E23 | B27: 110 | C27: 3859.652 | D27: =B27 -> 110 | E27: =C27-MAX($C$5:$C$76) -> -23.787 | F27: 108.4 | G27: -23.787
A28: E24 | B28: 115 | C28: 3860.308 | D28: =B28 -> 115 | E28: =C28-MAX($C$5:$C$76) -> -23.131 | F28: 113.4 | G28: -23.131 | H28: 113.4 | I28: -23.131
A29: E25 | B29: 120 | C29: 3861.019 | D29: =B29 -> 120 | E29: =C29-MAX($C$5:$C$76) -> -22.42 | F29: 118.4 | G29: -22.42 | H29: 118.4 | I29: -22.42
A30: E26 | B30: 125 | C30: 3861.839 | D30: =B30 -> 125 | E30: =C30-MAX($C$5:$C$76) -> -21.6 | F30: 123.3 | G30: -21.6 | H30: 123.3 | I30: -21.6
A31: E27 | B31: 130 | C31: 3861.73 | D31: =B31 -> 130 | E31: =C31-MAX($C$5:$C$76) -> -21.709 | F31: 128.2 | G31: -21.709 | H31: 128.2 | I31: -21.709
A32: E28 | B32: 135 | C32: 3862.493 | D32: =B32 -> 135 | E32: =C32-MAX($C$5:$C$76) -> -20.946 | F32: 133.2 | G32: -20.946 | H32: 133.2 | I32: -20.946
A33: E29 | B33: 140 | C33: 3863.137 | D33: =B33 -> 140 | E33: =C33-MAX($C$5:$C$76) -> -20.302 | F33: 138.2 | G33: -20.302 | H33: 138.2 | I33: -20.302
A34: E30 | B34: 145 | C34: 3863.678 | D34: =B34 -> 145 | E34: =C34-MAX($C$5:$C$76) -> -19.761 | F34: 143.2 | G34: -19.761 | H34: 143.2 | I34: -19.761
A35: E31 | B35: 150 | C35: 3863.512 | D35: =B35 -> 150 | E35: =C35-MAX($C$5:$C$76) -> -19.927 | F35: 148.2 | G35: -19.927 | H35: 148.2 | I35: -19.927
A36: E32 | B36: 155 | C36: 3862.611 | D36: =B36 -> 155 | E36: =C36-MAX($C$5:$C$76) -> -20.828 | F36: 153.2 | G36: -20.828 | H36: 153.2 | I36: -20.828
A37: E33 | B37: 160 | C37: 3862.605 | D37: =B37 -> 160 | E37: =C37-MAX($C$5:$C$76) -> -20.834 | F37: 158.1 | G37: -20.834 | H37: 158.1 | I37: -20.834
A38: E34 | B38: 165 | C38: 3861.233 | D38: =B38 -> 165 | E38: =C38-MAX($C$5:$C$76) -> -22.206 | F38: 162.9 | G38: -22.206 | H38: 162.9 | I38: -22.206
A39: E35 | B39: 170 | C39: 3859.786 | D39: =B39 -> 170 | E39: =C39-MAX($C$5:$C$76) -> -23.653 | F39: 167.9 | G39: -23.653 | H39: 167.9 | I39: -23.653
... A71: E67 | B71: 350 | C71: 3883.273 | D71: =B71 -> 350 | E71: =C71-MAX($C$5:$C$76) -> -0.166 | F71: 322.3 | G71: -0.166 | H71: 322.3 | I71: -0.166
A72: E68 | B72: 355 | C72: 3883.225 | D72: =B72 -> 355 | E72: =C72-MAX($C$5:$C$76) -> -0.214 | F72: 327.3 | G72: -0.214
A73: E69 | B73: 360 | C73: 3883.439 | D73: =B73 -> 360 | E73: =C73-MAX($C$5:$C$76) -> 0 | F73: 332.2 | G73: 0
A74: E70 | B74: 365 | C74: 3883.2 | D74: =B74 -> 365 | E74: =C74-MAX($C$5:$C$76) -> -0.239 | F74: 337.2 | G74: -0.239
A75: E71 | B75: 370 | C75: 3882.701 | D75: =B75 -> 370 | E75: =C75-MAX($C$5:$C$76) -> -0.738 | F75: 342.2 | G75: -0.738
A76: E72 | B76: 375 | C76: 3882.802 | D76: =B76 -> 375 | E76: =C76-MAX($C$5:$C$76) -> -0.637 | F76: 347.2 | G76: -0.637

Sheet abra05
A1: G1 = E1 | B1: ERT | D1: ERT depth | F1: ERT true | M1: Make RST start with highest point at point 0 for PJI | R1: RST max= | S1: =MAX(J2:J27) -> -44.2
H2: offset | I2: =I3-7.5 -> -7.5 | J2: -68.9 | M2: RST final | P2: ERT final
A3: E1 | B3: 0 | C3: 0 | D3: =B3 -> 0 | E3: =C3-MAX(C3:C50) -> -68.9 | F3: 0 | G3: =E3 -> -68.9 | H3: G1 | I3: =F3 -> 0 | J3: =G3 -> -68.9 | M3: =I2 -> -7.5 | N3: =J2-$S$1 -> -24.7 | P3: =F3 -> 0 | Q3: =G3-$S$1 -> -24.7
A4: E2 | B4: 5 | C4: 0.4 | D4: =B4 -> 5 | E4: =C4-MAX($C$4:$C$51) -> -68.5 | F4: =F3+(SQRT((D4-D3)^2-(E4-E3)^2)) -> 4.9839743 | G4: =E4 -> -68.5 | H4: G2 | I4: =F4 -> 4.9839743 | J4: =G4 -> -68.5 | M4: =I3 -> 0 | N4: =J3-$S$1 -> -24.7 | P4: =F4 -> 4.9839743 | Q4: =G4-$S$1 -> -24.3
A5: E3 | B5: 10 | C5: 0.6 | D5: =B5 -> 10 | E5: =C5-MAX($C$4:$C$51) -> -68.3 | F5: =F4+(SQRT((D5-D4)^2-(E5-E4)^2)) -> 9.9799727 | G5: =E5 -> -68.3 | H5: G3 | I5: =F5 -> 9.9799727 | J5: =G5 -> -68.3 | M5: =I4 -> 4.9839743 | N5: =J4-$S$1 -> -24.3 | P5: =F5 -> 9.9799727 | Q5: =G5-$S$1 -> -24.1
A6: E4 | B6: 15 | C6: 0.9 | D6: =B6 -> 15 | E6: =C6-MAX($C$4:$C$51) -> -68 | F6: =F5+(SQRT((D6-D5)^2-(E6-E5)^2)) -> 14.970965 | G6: =E6 -> -68 | H6: G4 | I6: =F6 -> 14.970965 | J6: =G6 -> -68 | M6: =I5 -> 9.9799727 | N6: =J5-$S$1 -> -24.1 | P6: =F6 -> 14.970965 | Q6: =G6-$S$1 -> -23.8
A7: E5 | B7: 20 | C7: 1 | D7: =B7 -> 20 | E7: =C7-MAX($C$4:$C$51) -> -67.9 | F7: =F6+(SQRT((D7-D6)^2-(E7-E6)^2)) -> 19.969965 | G7: =E7 -> -67.9 | H7: G5 | I7: =F7 -> 19.969965 | J7: =G7 -> -67.9 | M7: =I6 -> 14.970965 | N7: =J6-$S$1 -> -23.8 | P7: =F7 -> 19.969965 | Q7: =G7-$S$1 -> -23.7
A8: E6 | B8: 25 | C8: 1.5 | D8: =B8 -> 25 | E8: =C8-MAX($C$4:$C$51) -> -67.4 | F8: =F7+(SQRT((D8-D7)^2-(E8-E7)^2)) -> 24.944902 | G8: =E8 -> -67.4 | H8: G6 | I8: =F8 -> 24.944902 | J8: =G8 -> -67.4 | M8: =I7 -> 19.969965 | N8: =J7-$S$1 -> -23.7 | P8: =F8 -> 24.944902 | Q8: =G8-$S$1 -> -23.2
A9: E7 | B9: 30 | C9: 2.1 | D9: =B9 -> 30 | E9: =C9-MAX($C$4:$C$51) -> -66.8 | F9: =F8+(SQRT((D9-D8)^2-(E9-E8)^2)) -> 29.908771 | G9: =E9 -> -66.8 | H9: G7 | I9: =F9 -> 29.908771 | J9: =G9 -> -66.8 | M9: =I8 -> 24.944902 | N9: =J8-$S$1 -> -23.2 | P9: =F9 -> 29.908771 | Q9: =G9-$S$1 -> -22.6
A10: E8 | B10: 35 | C10: 2.5 | D10: =B10 -> 35 | E10: =C10-MAX($C$4:$C$51) -> -66.4 | F10: =F9+(SQRT((D10-D9)^2-(E10-E9)^2)) -> 34.892745 | G10: =E10 -> -66.4 | H10: G8 | I10: =F10 -> 34.892745 | J10: =G10 -> -66.4 | M10: =I9 -> 29.908771 | N10: =J9-$S$1 -> -22.6 | P10: =F10 -> 34.892745 | Q10: =G10-$S$1 -> -22.2
A11: E9 | B11: 40 | C11: 3 | D11: =B11 -> 40 | E11: =C11-MAX($C$4:$C$51) -> -65.9 | F11: =F10+(SQRT((D11-D10)^2-(E11-E10)^2)) -> 39.867683 | G11: =E11 -> -65.9 | H11: G9 | I11: =F11 -> 39.867683 | J11: =G11 -> -65.9 | M11: =I10 -> 34.892745 | N11: =J10-$S$1 -> -22.2 | P11: =F11 -> 39.867683 | Q11: =G11-$S$1 -> -21.7
A12: E10 | B12: 45 | C12: 3.9 | D12: =B12 -> 45 | E12: =C12-MAX($C$4:$C$51) -> -65 | F12: =F11+(SQRT((D12-D11)^2-(E12-E11)^2)) -> 44.786016 | G12: =E12 -> -65 | H12: G10 | I12: =F12 -> 44.786016 | J12: =G12 -> -65 | M12: =I11 -> 39.867683 | N12: =J11-$S$1 -> -21.7 | P12: =F12 -> 44.786016 | Q12: =G12-$S$1 -> -20.8
A13: E11 | B13: 50 | C13: 4.6 | D13: =B13 -> 50 | E13: =C13-MAX($C$4:$C$51) -> -64.3 | F13: =F12+(SQRT((D13-D12)^2-(E13-E12)^2)) -> 49.736773 | G13: =E13 -> -64.3 | H13: G11 | I13: =F13 -> 49.736773 | J13: =G13 -> -64.3 | M13: =I12 -> 44.786016 | N13: =J12-$S$1 -> -20.8 | P13: =F13 -> 49.736773 | Q13: =G13-$S$1 -> -20.1
A14: E12 | B14: 55 | C14: 6.4 | D14: =B14 -> 55 | E14: =C14-MAX($C$4:$C$51) -> -62.5 | F14: =F13+(SQRT((D14-D13)^2-(E14-E13)^2)) -> 54.401535 | G14: =E14 -> -62.5 | H14: G12 | I14: =F14 -> 54.401535 | J14: =G14 -> -62.5 | M14: =I13 -> 49.736773 | N14: =J13-$S$1 -> -20.1 | P14: =F14 -> 54.401535 | Q14: =G14-$S$1 -> -18.3
A15: E13 | B15: 60 | C15: 8.2 | D15: =B15 -> 60 | E15: =C15-MAX($C$4:$C$51) -> -60.7 | F15: =F14+(SQRT((D15-D14)^2-(E15-E14)^2)) -> 59.066296 | G15: =E15 -> -60.7 | H15: G13 | I15: =F15 -> 59.066296 | J15: =G15 -> -60.7 | M15: =I14 -> 54.401535 | N15: =J14-$S$1 -> -18.3 | P15: =F15 -> 59.066296 | Q15: =G15-$S$1 -> -16.5
... A26: E24 | B26: 115 | C26: 23.5 | D26: =B26 -> 115 | E26: =C26-MAX($C$4:$C$51) -> -45.4 | F26: =F25+(SQRT((D26-D25)^2-(E26-E25)^2)) -> 111.86073 | G26: =E26 -> -45.4 | H26: G24 | I26: =F26 -> 111.86073 | J26: =G26 -> -45.4 | M26: =I25 -> 107.06073 | N26: =J25-$S$1 -> -2.6 | P26: =F26 -> 111.86073 | Q26: =G26-$S$1 -> -1.2
A27: E25 | B27: 120 | C27: 24.7 | D27: =B27 -> 120 | E27: =C27-MAX($C$4:$C$51) -> -44.2 | F27: =F26+(SQRT((D27-D26)^2-(E27-E26)^2)) -> 116.71459 | G27: =E27 -> -44.2 | H27: offset | I27: =I26+7.5 -> 119.36073 | J27: =G27 -> -44.2 | M27: =I26 -> 111.86073 | N27: =J26-$S$1 -> -1.2 | P27: =F27 -> 116.71459 | Q27: =G27-$S$1 -> 0
A28: E26 | B28: 125 | C28: 26.1 | D28: =B28 -> 125 | E28: =C28-MAX($C$4:$C$51) -> -42.8 | F28: =F27+(SQRT((D28-D27)^2-(E28-E27)^2)) -> 121.51459 | G28: =E28 -> -42.8 | M28: =I27 -> 119.36073 | N28: =J27-$S$1 -> 0 | P28: =F28 -> 121.51459 | Q28: =G28-$S$1 -> 1.4
A29: E27 | B29: 130 | C29: 27.8 | D29: =B29 -> 130 | E29: =C29-MAX($C$4:$C$51) -> -41.1 | F29: =F28+(SQRT((D29-D28)^2-(E29-E28)^2)) -> 126.21672 | G29: =E29 -> -41.1 | P29: =F29 -> 126.21672 | Q29: =G29-$S$1 -> 3.1
A30: E28 | B30: 135 | C30: 29.7 | D30: =B30 -> 135 | E30: =C30-MAX($C$4:$C$51) -> -39.2 | F30: =F29+(SQRT((D30-D29)^2-(E30-E29)^2)) -> 130.84165 | G30: =E30 -> -39.2 | P30: =F30 -> 130.84165 | Q30: =G30-$S$1 -> 5
A31: E29 | B31: 140 | C31: 31.6 | D31: =B31 -> 140 | E31: =C31-MAX($C$4:$C$51) -> -37.3 | F31: =F30+(SQRT((D31-D30)^2-(E31-E30)^2)) -> 135.46658 | G31: =E31 -> -37.3 | P31: =F31 -> 135.46658 | Q31: =G31-$S$1 -> 6.9
A32: E30 | B32: 145 | C32: 33.3 | D32: =B32 -> 145 | E32: =C32-MAX($C$4:$C$51) -> -35.6 | F32: =F31+(SQRT((D32-D31)^2-(E32-E31)^2)) -> 140.16871 | G32: =E32 -> -35.6 | P32: =F32 -> 140.16871 | Q32: =G32-$S$1 -> 8.6
A33: E31 | B33: 150 | C33: 34.7 | D33: =B33 -> 150 | E33: =C33-MAX($C$4:$C$51) -> -34.2 | F33: =F32+(SQRT((D33-D32)^2-(E33-E32)^2)) -> 144.96871 | G33: =E33 -> -34.2 | P33: =F33 -> 144.96871 | Q33: =G33-$S$1 -> 10
A34: E32 | B34: 155 | C34: 36.2 | D34: =B34 -> 155 | E34: =C34-MAX($C$4:$C$51) -> -32.7 | F34: =F33+(SQRT((D34-D33)^2-(E34-E33)^2)) -> 149.73841 | G34: =E34 -> -32.7 | P34: =F34 -> 149.73841 | Q34: =G34-$S$1 -> 11.5
A35: E33 | B35: 160 | C35: 37.6 | D35: =B35 -> 160 | E35: =C35-MAX($C$4:$C$51) -> -31.3 | F35: =F34+(SQRT((D35-D34)^2-(E35-E34)^2)) -> 154.53841 | G35: =E35 -> -31.3 | P35: =F35 -> 154.53841 | Q35: =G35-$S$1 -> 12.9
A36: E34 | B36: 165 | C36: 39.3 | D36: =B36 -> 165 | E36: =C36-MAX($C$4:$C$51) -> -29.6 | F36: =F35+(SQRT((D36-D35)^2-(E36-E35)^2)) -> 159.24053 | G36: =E36 -> -29.6 | P36: =F36 -> 159.24053 | Q36: =G36-$S$1 -> 14.6
A37: E35 | B37: 170 | C37: 40.8 | D37: =B37 -> 170 | E37: =C37-MAX($C$4:$C$51) -> -28.1 | F37: =F36+(SQRT((D37-D36)^2-(E37-E36)^2)) -> 164.01023 | G37: =E37 -> -28.1 | P37: =F37 -> 164.01023 | Q37: =G37-$S$1 -> 16.1
A38: E36 | B38: 175 | C38: 42.7 | D38: =B38 -> 175 | E38: =C38-MAX($C$4:$C$51) -> -26.2 | F38: =F37+(SQRT((D38-D37)^2-(E38-E37)^2)) -> 168.63516 | G38: =E38 -> -26.2 | P38: =F38 -> 168.63516 | Q38: =G38-$S$1 -> 18
A39: E37 | B39: 180 | C39: 44.6 | D39: =B39 -> 180 | E39: =C39-MAX($C$4:$C$51) -> -24.3 | F39: =F38+(SQRT((D39-D38)^2-(E39-E38)^2)) -> 173.26009 | G39: =E39 -> -24.3 | P39: =F39 -> 173.26009 | Q39: =G39-$S$1 -> 19.9
A40: E38 | B40: 185 | C40: 46.3 | D40: =B40 -> 185 | E40: =C40-MAX($C$4:$C$51) -> -22.6 | F40: =F39+(SQRT((D40-D39)^2-(E40-E39)^2)) -> 177.96222 | G40: =E40 -> -22.6 | P40: =F40 -> 177.96222 | Q40: =G40-$S$1 -> 21.6
... A50: E48 | B50: 235 | C50: 68.9 | D50: =B50 -> 235 | E50: =C50-MAX($C$4:$C$51) -> 0 | F50: =F49+(SQRT((D50-D49)^2-(E50-E49)^2)) -> 222.31805 | G50: =E50 -> 0 | P50: =F50 -> 222.31805 | Q50: =G50-$S$1 -> 44.2

Sheet abra03
A1: RST | E1: ERT
A2: =-7.5 -> -7.5 | B2: -0.5 | E2: 0 | F2: 0
A3: =-3.75 -> -3.75 | B3: -0.25 | E3: 4.9183331 | F3: -0.9
A4: 0 | B4: 0 | E4: 9.8366661 | F4: -1.8
A5: 2.45 | B5: -0.45 | E5: 14.754999 | F5: -2.7
A6: 4.9 | B6: -0.9 | E6: 19.673332 | F6: -3.6
A7: 7.35 | B7: -1.35 | E7: 24.572312 | F7: -4.6
A8: 9.8 | B8: -1.8 | E8: 29.507897 | F8: -5.4
A9: 12.3 | B9: -2.25 | E9: 34.458654 | F9: -6.1
A10: 14.8 | B10: -2.7 | E10: 39.394239 | F10: -6.9
A11: 17.25 | B11: -3.15 | E11: 44.312572 | F11: -7.8
A12: 19.7 | B12: -3.6 | E12: 49.211552 | F12: -8.8
A13: 22.15 | B13: -4.1 | E13: 54.195526 | F13: -9.2
A14: 24.6 | B14: -4.6 | E14: 59.170463 | F14: -9.7
A15: 27.05 | B15: -5 | E15: 63.998506 | F15: -11
... A88: 212.5 | B88: -30 | E88: 421.55955 | F88: -57.1
E89: 426.53449 | F89: -57.6
E90: 431.50942 | F90: -58.1
E91: 436.50042 | F91: -58.4
E92: 441.48439 | F92: -58.8
E93: 446.46836 | F93: -59.2
E94: 451.4433 | F94: -59.7
E95: 456.42728 | F95: -60.1
E96: 461.41125 | F96: -60.5
E97: 466.38619 | F97: -61

Sheet abra09
A1: abra09 | C1: G1 = E48
C3: ERT (original) | F3: RST | I3: RST (new)
A4: #ERT | B4: #GST | C4: x | D4: z | E4: z_depth | F4: x | G4: z_alt | H4: z_depth | I4: x | J4: z
A5: E1 | C5: 0 | D5: 3864.187 | E5: =D5-MAX(D5:D76) -> -31.563 | K5: =C5 -> 0 | L5: =E5 -> -31.563
A6: E2 | C6: 4.9942367 | D6: 3864.427 | E6: =D6-MAX(D6:D77) -> -31.323 | K6: =C6 -> 4.9942367 | L6: =E6 -> -31.323
A7: E3 | C7: 9.9596602 | D7: 3865.014 | E7: =D7-MAX(D7:D78) -> -30.736 | K7: =C7 -> 9.9596602 | L7: =E7 -> -30.736
A8: E4 | C8: 14.911122 | D8: 3865.709 | E8: =D8-MAX(D8:D79) -> -30.041 | K8: =C8 -> 14.911122 | L8: =E8 -> -30.041
A9: E5 | C9: 19.867371 | D9: 3866.369 | E9: =D9-MAX(D9:D80) -> -29.381 | K9: =C9 -> 19.867371 | L9: =E9 -> -29.381
A10: E6 | C10: 24.855592 | D10: 3866.712 | E10: =D10-MAX(D10:D81) -> -29.038 | K10: =C10 -> 24.855592 | L10: =E10 -> -29.038
A11: E7 | C11: 29.844953 | D11: 3867.038 | E11: =D11-MAX(D11:D82) -> -28.712 | K11: =C11 -> 29.844953 | L11: =E11 -> -28.712
A12: E8 | C12: 34.841417 | D12: 3866.85 | E12: =D12-MAX(D12:D83) -> -28.9 | K12: =C12 -> 34.841417 | L12: =E12 -> -28.9
A13: E9 | C13: 39.83773 | D13: 3866.658 | E13: =D13-MAX(D13:D84) -> -29.092 | K13: =C13 -> 39.83773 | L13: =E13 -> -29.092
A14: E10 | C14: 44.830965 | D14: 3866.398 | E14: =D14-MAX(D14:D85) -> -29.352 | K14: =C14 -> 44.830965 | L14: =E14 -> -29.352
A15: E11 | C15: 49.827831 | D15: 3866.221 | E15: =D15-MAX(D15:D86) -> -29.529 | K15: =C15 -> 49.827831 | L15: =E15 -> -29.529
A16: E12 | C16: 54.802466 | D16: 3865.718 | E16: =D16-MAX(D16:D87) -> -30.032 | K16: =C16 -> 54.802466 | L16: =E16 -> -30.032
... A50: E46 | C50: 222.97392 | D50: 3872.735 | E50: =D50-MAX(D50:D121) -> -23.015 | K50: =C50 -> 222.97392 | L50: =E50 -> -23.015
A51: E47 | B51: offset | C51: 227.85874 | D51: 3873.802 | E51: =D51-MAX(D51:D122) -> -21.948 | K51: =C51 -> 227.85874 | L51: =E51 -> -21.948
A52: E48 | B52: G1 | C52: 232.8469 | D52: 3874.146 | E52: =D52-MAX(D52:D123) -> -21.604 | F52: =C52 -> 232.8469 | G52: =D52 -> 3874.146 | H52: =E52 -> -21.604 | I52: =I53-7.5 -> 226.39925 | J52: -22 | K52: =C52 -> 232.8469 | L52: =E52 -> -21.604
A53: E49 | B53: G2 | C53: 233.89925 | D53: 3877.034 | E53: =D53-MAX(D53:D124) -> -18.716 | F53: =C53 -> 233.89925 | G53: =D53 -> 3877.034 | H53: =E53 -> -18.716 | I53: =F53 -> 233.89925 | J53: =H53 -> -18.716 | K53: =C53 -> 233.89925 | L53: =E53 -> -18.716
A54: E50 | B54: G3 | C54: 238.69397 | D54: 3880.452 | E54: =D54-MAX(D54:D125) -> -15.298 | F54: =C54 -> 238.69397 | G54: =D54 -> 3880.452 | H54: =E54 -> -15.298 | I54: =F54 -> 238.69397 | J54: =H54 -> -15.298 | K54: =C54 -> 238.69397 | L54: =E54 -> -15.298
A55: E51 | B55: G4 | C55: 243.52201 | D55: 3881.752 | E55: =D55-MAX(D55:D126) -> -13.998 | F55: =C55 -> 243.52201 | G55: =D55 -> 3881.752 | H55: =E55 -> -13.998 | I55: =F55 -> 243.52201 | J55: =H55 -> -13.998 | K55: =C55 -> 243.52201 | L55: =E55 -> -13.998
A56: E52 | B56: G5 | C56: 248.50946 | D56: 3882.106 | E56: =D56-MAX(D56:D127) -> -13.644 | F56: =C56 -> 248.50946 | G56: =D56 -> 3882.106 | H56: =E56 -> -13.644 | I56: =F56 -> 248.50946 | J56: =H56 -> -13.644 | K56: =C56 -> 248.50946 | L56: =E56 -> -13.644
A57: E53 | B57: G6 | C57: 253.45305 | D57: 3882.855 | E57: =D57-MAX(D57:D128) -> -12.895 | F57: =C57 -> 253.45305 | G57: =D57 -> 3882.855 | H57: =E57 -> -12.895 | I57: =F57 -> 253.45305 | J57: =H57 -> -12.895 | K57: =C57 -> 253.45305 | L57: =E57 -> -12.895
A58: E54 | B58: G7 | C58: 258.45088 | D58: 3883.002 | E58: =D58-MAX(D58:D129) -> -12.748 | F58: =C58 -> 258.45088 | G58: =D58 -> 3883.002 | H58: =E58 -> -12.748 | I58: =F58 -> 258.45088 | J58: =H58 -> -12.748 | K58: =C58 -> 258.45088 | L58: =E58 -> -12.748
A59: E55 | B59: G8 | C59: 263.34216 | D59: 3884.039 | E59: =D59-MAX(D59:D130) -> -11.711 | F59: =C59 -> 263.34216 | G59: =D59 -> 3884.039 | H59: =E59 -> -11.711 | I59: =F59 -> 263.34216 | J59: =H59 -> -11.711 | K59: =C59 -> 263.34216 | L59: =E59 -> -11.711
A60: E56 | B60: G9 | C60: 268.17289 | D60: 3885.329 | E60: =D60-MAX(D60:D131) -> -10.421 | F60: =C60 -> 268.17289 | G60: =D60 -> 3885.329 | H60: =E60 -> -10.421 | I60: =F60 -> 268.17289 | J60: =H60 -> -10.421 | K60: =C60 -> 268.17289 | L60: =E60 -> -10.421
A61: E57 | B61: G10 | C61: 273.13542 | D61: 3885.94 | E61: =D61-MAX(D61:D132) -> -9.81 | F61: =C61 -> 273.13542 | G61: =D61 -> 3885.94 | H61: =E61 -> -9.81 | I61: =F61 -> 273.13542 | J61: =H61 -> -9.81 | K61: =C61 -> 273.13542 | L61: =E61 -> -9.81
A62: E58 | B62: G11 | C62: 278.13507 | D62: 3885.999 | E62: =D62-MAX(D62:D133) -> -9.751 | F62: =C62 -> 278.13507 | G62: =D62 -> 3885.999 | H62: =E62 -> -9.751 | I62: =F62 -> 278.13507 | J62: =H62 -> -9.751 | K62: =C62 -> 278.13507 | L62: =E62 -> -9.751
A63: E59 | B63: G12 | C63: 282.29898 | D63: 3888.767 | E63: =D63-MAX(D63:D134) -> -6.983 | F63: =C63 -> 282.29898 | G63: =D63 -> 3888.767 | H63: =E63 -> -6.983 | I63: =F63 -> 282.29898 | J63: =H63 -> -6.983 | K63: =C63 -> 282.29898 | L63: =E63 -> -6.983
A64: E60 | B64: G13 | C64: 287.15604 | D64: 3889.954 | E64: =D64-MAX(D64:D135) -> -5.796 | F64: =C64 -> 287.15604 | G64: =D64 -> 3889.954 | H64: =E64 -> -5.796 | I64: =F64 -> 287.15604 | J64: =H64 -> -5.796 | K64: =C64 -> 287.15604 | L64: =E64 -> -5.796
... A75: E71 | B75: G24 | C75: 341.5695 | D75: 3895.74 | E75: =D75-MAX(D75:D146) -> -0.01 | F75: =C75 -> 341.5695 | G75: =D75 -> 3895.74 | H75: =E75 -> -0.01 | I75: =F75 -> 341.5695 | J75: =H75 -> -0.01 | K75: =C75 -> 341.5695 | L75: =E75 -> -0.01
A76: E72 | B76: offset | C76: 346.56949 | D76: 3895.75 | E76: =D76-MAX(D76:D147) -> 0 | H76: =E76 -> 0 | I76: =C76 -> 346.56949 | J76: =H76 -> 0 | K76: =C76 -> 346.56949 | L76: =E76 -> 0
I77: =I76+7.5 -> 354.06949 | J77: =H77 -> 0

Sheet abra10
A1: abra10 | C1: G1 = E1 | N1: Make max RST point = 0 | Q1: RST max = | R1: =MAX(J5:J30) -> -8.02
C3: ERT (original) | F3: RST | I3: RST (new) | N3: RST final | Q3: ERT final
A4: #ERT | B4: #GST | C4: x | D4: z | E4: z_depth | F4: x | G4: z_alt | H4: z_depth | I4: x | J4: z
B5: offset | F5: -7.5 | G5: =G6 -> 3799.55 | H5: =H6 -> -28.05 | I5: =F5 -> -7.5 | J5: =H5 -> -28.05 | N5: =I5 -> -7.5 | O5: =J5-$R$1 -> -20.03 | Q5: =C6 -> 0 | R5: =E6-$R$1 -> -20.03
A6: E1 | B6: G1 | C6: 0 | D6: 3799.55 | E6: =D6-MAX(D6:D53) -> -28.05 | F6: =C6 -> 0 | G6: =D6 -> 3799.55 | H6: =E6 -> -28.05 | I6: =F6 -> 0 | J6: =H6 -> -28.05 | K6: =C6 -> 0 | L6: =E6 -> -28.05 | N6: =I6 -> 0 | O6: =J6-$R$1 -> -20.03 | Q6: =C7 -> 4.9999964 | R6: =E7-$R$1 -> -20.02
A7: E2 | B7: G2 | C7: 4.9999964 | D7: 3799.56 | E7: =D7-MAX(D7:D54) -> -28.04 | F7: =C7 -> 4.9999964 | G7: =D7 -> 3799.56 | H7: =E7 -> -28.04 | I7: =F7 -> 4.9999964 | J7: =H7 -> -28.04 | K7: =C7 -> 4.9999964 | L7: =E7 -> -28.04 | N7: =I7 -> 4.9999964 | O7: =J7-$R$1 -> -20.02 | Q7: =C8 -> 9.8722516 | R7: =E8-$R$1 -> -18.9
A8: E3 | B8: G3 | C8: 9.8722516 | D8: 3800.68 | E8: =D8-MAX(D8:D55) -> -26.92 | F8: =C8 -> 9.8722516 | G8: =D8 -> 3800.68 | H8: =E8 -> -26.92 | I8: =F8 -> 9.8722516 | J8: =H8 -> -26.92 | K8: =C8 -> 9.8722516 | L8: =E8 -> -26.92 | N8: =I8 -> 9.8722516 | O8: =J8-$R$1 -> -18.9 | Q8: =C9 -> 14.736783 | R8: =E9-$R$1 -> -17.74
A9: E4 | B9: G4 | C9: 14.736783 | D9: 3801.84 | E9: =D9-MAX(D9:D56) -> -25.76 | F9: =C9 -> 14.736783 | G9: =D9 -> 3801.84 | H9: =E9 -> -25.76 | I9: =F9 -> 14.736783 | J9: =H9 -> -25.76 | K9: =C9 -> 14.736783 | L9: =E9 -> -25.76 | N9: =I9 -> 14.736783 | O9: =J9-$R$1 -> -17.74 | Q9: =C10 -> 19.654198 | R9: =E10-$R$1 -> -16.84
A10: E5 | B10: G5 | C10: 19.654198 | D10: 3802.74 | E10: =D10-MAX(D10:D57) -> -24.86 | F10: =C10 -> 19.654198 | G10: =D10 -> 3802.74 | H10: =E10 -> -24.86 | I10: =F10 -> 19.654198 | J10: =H10 -> -24.86 | K10: =C10 -> 19.654198 | L10: =E10 -> -24.86 | N10: =I10 -> 19.654198 | O10: =J10-$R$1 -> -16.84 | Q10: =C11 -> 24.474063 | R10: =E11-$R$1 -> -15.51
A11: E6 | B11: G6 | C11: 24.474063 | D11: 3804.07 | E11: =D11-MAX(D11:D58) -> -23.53 | F11: =C11 -> 24.474063 | G11: =D11 -> 3804.07 | H11: =E11 -> -23.53 | I11: =F11 -> 24.474063 | J11: =H11 -> -23.53 | K11: =C11 -> 24.474063 | L11: =E11 -> -23.53 | N11: =I11 -> 24.474063 | O11: =J11-$R$1 -> -15.51 | Q11: =C12 -> 29.387756 | R11: =E12-$R$1 -> -14.58
A12: E7 | B12: G7 | C12: 29.387756 | D12: 3805 | E12: =D12-MAX(D12:D59) -> -22.6 | F12: =C12 -> 29.387756 | G12: =D12 -> 3805 | H12: =E12 -> -22.6 | I12: =F12 -> 29.387756 | J12: =H12 -> -22.6 | K12: =C12 -> 29.387756 | L12: =E12 -> -22.6 | N12: =I12 -> 29.387756 | O12: =J12-$R$1 -> -14.58 | Q12: =C13 -> 34.305355 | R12: =E13-$R$1 -> -13.68
A13: E8 | B13: G8 | C13: 34.305355 | D13: 3805.9 | E13: =D13-MAX(D13:D60) -> -21.7 | F13: =C13 -> 34.305355 | G13: =D13 -> 3805.9 | H13: =E13 -> -21.7 | I13: =F13 -> 34.305355 | J13: =H13 -> -21.7 | K13: =C13 -> 34.305355 | L13: =E13 -> -21.7 | N13: =I13 -> 34.305355 | O13: =J13-$R$1 -> -13.68 | Q13: =C14 -> 39.125496 | R13: =E14-$R$1 -> -12.35
A14: E9 | B14: G9 | C14: 39.125496 | D14: 3807.23 | E14: =D14-MAX(D14:D61) -> -20.37 | F14: =C14 -> 39.125496 | G14: =D14 -> 3807.23 | H14: =E14 -> -20.37 | I14: =F14 -> 39.125496 | J14: =H14 -> -20.37 | K14: =C14 -> 39.125496 | L14: =E14 -> -20.37 | N14: =I14 -> 39.125496 | O14: =J14-$R$1 -> -12.35 | Q14: =C15 -> 44.06444 | R14: =E15-$R$1 -> -11.57
A15: E10 | B15: G10 | C15: 44.06444 | D15: 3808.01 | E15: =D15-MAX(D15:D62) -> -19.59 | F15: =C15 -> 44.06444 | G15: =D15 -> 3808.01 | H15: =E15 -> -19.59 | I15: =F15 -> 44.06444 | J15: =H15 -> -19.59 | K15: =C15 -> 44.06444 | L15: =E15 -> -19.59 | N15: =I15 -> 44.06444 | O15: =J15-$R$1 -> -11.57 | Q15: =C16 -> 48.641759 | R15: =E16-$R$1 -> -9.56
A16: E11 | B16: G11 | C16: 48.641759 | D16: 3810.02 | E16: =D16-MAX(D16:D63) -> -17.58 | F16: =C16 -> 48.641759 | G16: =D16 -> 3810.02 | H16: =E16 -> -17.58 | I16: =F16 -> 48.641759 | J16: =H16 -> -17.58 | K16: =C16 -> 48.641759 | L16: =E16 -> -17.58 | N16: =I16 -> 48.641759 | O16: =J16-$R$1 -> -9.56 | Q16: =C17 -> 53.594891 | R16: =E17-$R$1 -> -8.87
A17: E12 | B17: G12 | C17: 53.594891 | D17: 3810.71 | E17: =D17-MAX(D17:D64) -> -16.89 | F17: =C17 -> 53.594891 | G17: =D17 -> 3810.71 | H17: =E17 -> -16.89 | I17: =F17 -> 53.594891 | J17: =H17 -> -16.89 | K17: =C17 -> 53.594891 | L17: =E17 -> -16.89 | N17: =I17 -> 53.594891 | O17: =J17-$R$1 -> -8.87 | Q17: =C18 -> 58.56499 | R17: =E18-$R$1 -> -8.33
... A29: E24 | B29: G24 | C29: 112.82601 | D29: 3819.18 | E29: =D29-MAX(D29:D76) -> -8.42 | F29: =C29 -> 112.82601 | G29: =D29 -> 3819.18 | H29: =E29 -> -8.42 | I29: =F29 -> 112.82601 | J29: =H29 -> -8.42 | K29: =C29 -> 112.82601 | L29: =E29 -> -8.42 | N29: =I29 -> 112.82601 | O29: =J29-$R$1 -> -0.4 | Q29: =C30 -> 117.80933 | R29: =E30-$R$1 -> 0
A30: E25 | B30: offset | C30: 117.80933 | D30: 3819.58 | E30: =D30-MAX(D30:D77) -> -8.02 | F30: =F29+7.5 -> 120.32601 | G30: =D30 -> 3819.58 | H30: =E30 -> -8.02 | I30: =F30 -> 120.32601 | J30: =H30 -> -8.02 | K30: =C30 -> 117.80933 | L30: =E30 -> -8.02 | N30: =I30 -> 120.32601 | O30: =J30-$R$1 -> 0 | Q30: =C31 -> 122.72056 | R30: =E31-$R$1 -> 0.94
A31: E26 | C31: 122.72056 | D31: 3820.52 | E31: =D31-MAX(D31:D78) -> -7.08 | K31: =C31 -> 122.72056 | L31: =E31 -> -7.08 | Q31: =C32 -> 127.60031 | R31: =E32-$R$1 -> 2.03
A32: E27 | C32: 127.60031 | D32: 3821.61 | E32: =D32-MAX(D32:D79) -> -5.99 | K32: =C32 -> 127.60031 | L32: =E32 -> -5.99 | Q32: =C33 -> 132.49908 | R32: =E33-$R$1 -> 3.03
A33: E28 | C33: 132.49908 | D33: 3822.61 | E33: =D33-MAX(D33:D80) -> -4.99 | K33: =C33 -> 132.49908 | L33: =E33 -> -4.99 | Q33: =C34 -> 137.49547 | R33: =E34-$R$1 -> 3.22
A34: E29 | C34: 137.49547 | D34: 3822.8 | E34: =D34-MAX(D34:D81) -> -4.8 | K34: =C34 -> 137.49547 | L34: =E34 -> -4.8 | Q34: =C35 -> 142.4699 | R34: =E35-$R$1 -> 3.73
A35: E30 | C35: 142.4699 | D35: 3823.31 | E35: =D35-MAX(D35:D82) -> -4.29 | K35: =C35 -> 142.4699 | L35: =E35 -> -4.29 | Q35: =C36 -> 147.46618 | R35: =E36-$R$1 -> 3.92
A36: E31 | C36: 147.46618 | D36: 3823.5 | E36: =D36-MAX(D36:D83) -> -4.1 | K36: =C36 -> 147.46618 | L36: =E36 -> -4.1 | Q36: =C37 -> 152.46342 | R36: =E37-$R$1 -> 4.09
A37: E32 | C37: 152.46342 | D37: 3823.67 | E37: =D37-MAX(D37:D84) -> -3.93 | K37: =C37 -> 152.46342 | L37: =E37 -> -3.93 | Q37: =C38 -> 157.44642 | R37: =E38-$R$1 -> 4.5
A38: E33 | C38: 157.44642 | D38: 3824.08 | E38: =D38-MAX(D38:D85) -> -3.52 | K38: =C38 -> 157.44642 | L38: =E38 -> -3.52 | Q38: =C39 -> 162.44498 | R38: =E39-$R$1 -> 4.38
A39: E34 | C39: 162.44498 | D39: 3823.96 | E39: =D39-MAX(D39:D86) -> -3.64 | K39: =C39 -> 162.44498 | L39: =E39 -> -3.64 | Q39: =C40 -> 167.44493 | R39: =E40-$R$1 -> 4.36
A40: E35 | C40: 167.44493 | D40: 3823.94 | E40: =D40-MAX(D40:D87) -> -3.66 | K40: =C40 -> 167.44493 | L40: =E40 -> -3.66 | Q40: =C41 -> 172.44485 | R40: =E41-$R$1 -> 4.39
A41: E36 | C41: 172.44485 | D41: 3823.97 | E41: =D41-MAX(D41:D88) -> -3.63 | K41: =C41 -> 172.44485 | L41: =E41 -> -3.63 | Q41: =C42 -> 177.42875 | R41: =E42-$R$1 -> 4.79
A42: E37 | C42: 177.42875 | D42: 3824.37 | E42: =D42-MAX(D42:D89) -> -3.23 | K42: =C42 -> 177.42875 | L42: =E42 -> -3.23 | Q42: =C43 -> 182.42773 | R42: =E43-$R$1 -> 4.69
... A52: E47 | C52: 227.21622 | D52: 3827.1 | E52: =D52-MAX(D52:D99) -> -0.5 | K52: =C52 -> 227.21622 | L52: =E52 -> -0.5 | Q52: =C53 -> 232.19176 | R52: =E53-$R$1 -> 8.02
A53: E48 | C53: 232.19176 | D53: 3827.6 | E53: =D53-MAX(D53:D100) -> 0 | K53: =C53 -> 232.19176 | L53: =E53 -> 0

Sheet GOL01
A1: GOL01 | C1: G1 = E25 | D1: ERT = 5m spacing, RST = 2.5 m spacing
C3: ERT (original) | F3: RST | I3: RST (new)
A4: #ERT | B4: #GST | C4: x | D4: z | E4: z_depth | F4: x | G4: z_alt | H4: z_depth | I4: x | J4: z
A7: E1 | C7: 0 | D7: 3220.831 | E7: =D7-MAX(D7:D54) -> -23.55 | K7: =C7 -> 0 | L7: =E7 -> -23.55
A8: E2 | C8: 4.9963506 | D8: 3220.64 | E8: =D8-MAX(D8:D55) -> -23.741 | K8: =C8 -> 4.9963506 | L8: =E8 -> -23.741
A9: E3 | C9: 9.9958605 | D9: 3220.57 | E9: =D9-MAX(D9:D56) -> -23.811 | K9: =C9 -> 9.9958605 | L9: =E9 -> -23.811
A10: E4 | C10: 14.916915 | D10: 3221.455 | E10: =D10-MAX(D10:D57) -> -22.926 | K10: =C10 -> 14.916915 | L10: =E10 -> -22.926
A11: E5 | C11: 19.913491 | D11: 3221.27 | E11: =D11-MAX(D11:D58) -> -23.111 | K11: =C11 -> 19.913491 | L11: =E11 -> -23.111
A12: E6 | C12: 24.906464 | D12: 3221.535 | E12: =D12-MAX(D12:D59) -> -22.846 | K12: =C12 -> 24.906464 | L12: =E12 -> -22.846
A13: E7 | C13: 29.873175 | D13: 3222.111 | E13: =D13-MAX(D13:D60) -> -22.27 | K13: =C13 -> 29.873175 | L13: =E13 -> -22.27
A14: E8 | C14: 34.792784 | D14: 3223.004 | E14: =D14-MAX(D14:D61) -> -21.377 | K14: =C14 -> 34.792784 | L14: =E14 -> -21.377
A15: E9 | C15: 39.614301 | D15: 3224.328 | E15: =D15-MAX(D15:D62) -> -20.053 | K15: =C15 -> 39.614301 | L15: =E15 -> -20.053
A16: E10 | C16: 44.429163 | D16: 3225.676 | E16: =D16-MAX(D16:D63) -> -18.705 | K16: =C16 -> 44.429163 | L16: =E16 -> -18.705
A17: E11 | C17: 49.428687 | D17: 3225.607 | E17: =D17-MAX(D17:D64) -> -18.774 | K17: =C17 -> 49.428687 | L17: =E17 -> -18.774
A18: E12 | C18: 54.427687 | D18: 3225.707 | E18: =D18-MAX(D18:D65) -> -18.674 | K18: =C18 -> 54.427687 | L18: =E18 -> -18.674
... A28: E22 | C28: 103.27793 | D28: 3226.33 | E28: =D28-MAX(D28:D75) -> -18.051 | K28: =C28 -> 103.27793 | L28: =E28 -> -18.051
A29: E23 | B29: offset | C29: 108.17712 | D29: 3227.329 | E29: =D29-MAX(D29:D76) -> -17.052 | F29: 112.5 | G29: 3245.881 | H29: =E29 -> -17.052 | I29: =F29 -> 112.5 | J29: =H29 -> -17.052 | K29: =C29 -> 108.17712 | L29: =E29 -> -17.052
A30: E24 | B30: offset | C30: 113.06346 | D30: 3228.389 | E30: =D30-MAX(D30:D77) -> -15.992 | F30: 117.5 | G30: 3244.881 | H30: =E30 -> -15.992 | I30: =F30 -> 117.5 | J30: =H30 -> -15.992 | K30: =C30 -> 113.06346 | L30: =E30 -> -15.992
A31: E25 | B31: G1 | C31: 118.05789 | D31: 3228.625 | E31: =D31-MAX(D31:D78) -> -15.756 | F31: 120 | G31: 3244.381 | H31: =E31 -> -15.756 | I31: =F31 -> 120 | J31: =H31 -> -15.756 | K31: =C31 -> 118.05789 | L31: =E31 -> -15.756
A32: E26 | B32: G2 | C32: 122.91835 | D32: 3229.798 | E32: =D32-MAX(D32:D79) -> -14.583 | F32: =C32+((C33-C32)/2) -> 125.40733 | G32: 3243.012 | H32: =E32 -> -14.583 | I32: =F32 -> 125.40733 | J32: =H32 -> -14.583 | K32: =C32 -> 122.91835 | L32: =E32 -> -14.583
A33: E27 | B33: G3 | C33: 127.89631 | D33: 3230.267 | E33: =D33-MAX(D33:D80) -> -14.114 | F33: =C33 -> 127.89631 | G33: 3241.326 | H33: =E33 -> -14.114 | I33: =F33 -> 127.89631 | J33: =H33 -> -14.114 | K33: =C33 -> 127.89631 | L33: =E33 -> -14.114
A34: E28 | B34: G4 | C34: 132.82844 | D34: 3231.088 | E34: =D34-MAX(D34:D81) -> -13.293 | F34: =C34+((C35-C34)/2)-0.5 -> 134.74802 | G34: 3239.598 | H34: =E34 -> -13.293 | I34: =F34 -> 134.74802 | J34: =H34 -> -13.293 | K34: =C34 -> 132.82844 | L34: =E34 -> -13.293
A35: E29 | B35: G5 | C35: 137.6676 | D35: 3229.83 | E35: =D35-MAX(D35:D82) -> -14.551 | F35: =C35 -> 137.6676 | G35: 3239.666 | H35: =E35 -> -14.551 | I35: =F35 -> 137.6676 | J35: =H35 -> -14.551 | K35: =C35 -> 137.6676 | L35: =E35 -> -14.551
A36: E30 | B36: G6 | C36: 142.63302 | D36: 3230.417 | E36: =D36-MAX(D36:D83) -> -13.964 | F36: =C36+((C37-C36)/2) -> 144.88579 | G36: 3239.1 | H36: =E36 -> -13.964 | I36: =F36 -> 144.88579 | J36: =H36 -> -13.964 | K36: =C36 -> 142.63302 | L36: =E36 -> -13.964
A37: E31 | B37: G7 | C37: 147.13855 | D37: 3232.585 | E37: =D37-MAX(D37:D84) -> -11.796 | F37: =C37 -> 147.13855 | G37: 3238.859 | H37: =E37 -> -11.796 | I37: =F37 -> 147.13855 | J37: =H37 -> -11.796 | K37: =C37 -> 147.13855 | L37: =E37 -> -11.796
A38: E32 | B38: G8 | C38: 152.13796 | D38: 3232.508 | E38: =D38-MAX(D38:D85) -> -11.873 | F38: =C38+((C39-C38)/2) -> 154.602 | G38: 3237.75 | H38: =E38 -> -11.873 | I38: =F38 -> 154.602 | J38: =H38 -> -11.873 | K38: =C38 -> 152.13796 | L38: =E38 -> -11.873
A39: E33 | B39: G9 | C39: 157.06604 | D39: 3233.353 | E39: =D39-MAX(D39:D86) -> -11.028 | F39: =C39 -> 157.06604 | G39: 3237.58 | H39: =E39 -> -11.028 | I39: =F39 -> 157.06604 | J39: =H39 -> -11.028 | K39: =C39 -> 157.06604 | L39: =E39 -> -11.028
A40: E34 | B40: G10 | C40: 161.96664 | D40: 3234.345 | E40: =D40-MAX(D40:D87) -> -10.036 | F40: =C40+((C41-C40)/2) -> 164.45883 | G40: 3237.533 | H40: =E40 -> -10.036 | I40: =F40 -> 164.45883 | J40: =H40 -> -10.036 | K40: =C40 -> 161.96664 | L40: =E40 -> -10.036
A41: E35 | B41: G11 | C41: 166.95102 | D41: 3234.74 | E41: =D41-MAX(D41:D88) -> -9.641 | F41: =C41 -> 166.95102 | G41: 3237.223 | H41: =E41 -> -9.641 | I41: =F41 -> 166.95102 | J41: =H41 -> -9.641 | K41: =C41 -> 166.95102 | L41: =E41 -> -9.641
A42: E36 | B42: G12 | C42: 171.78809 | D42: 3236.006 | E42: =D42-MAX(D42:D89) -> -8.375 | F42: =C42+((C43-C42)/2) -> 174.28733 | G42: 3236.129 | H42: =E42 -> -8.375 | I42: =F42 -> 174.28733 | J42: =H42 -> -8.375 | K42: =C42 -> 171.78809 | L42: =E42 -> -8.375
A43: E37 | B43: G13 | C43: 176.78657 | D43: 3236.129 | E43: =D43-MAX(D43:D90) -> -8.252 | F43: =C43 -> 176.78657 | G43: 3236.006 | H43: =E43 -> -8.252 | I43: =F43 -> 176.78657 | J43: =H43 -> -8.252 | K43: =C43 -> 176.78657 | L43: =E43 -> -8.252
A44: E38 | B44: G14 | C44: 181.66542 | D44: 3237.223 | E44: =D44-MAX(D44:D91) -> -7.158 | F44: =C44+((C45-C44)/2) -> 184.16061 | G44: 3234.74 | H44: =E44 -> -7.158 | I44: =F44 -> 184.16061 | J44: =H44 -> -7.158 | K44: =C44 -> 181.66542 | L44: =E44 -> -7.158
A45: E39 | B45: G15 | C45: 186.6558 | D45: 3237.533 | E45: =D45-MAX(D45:D92) -> -6.848 | F45: =C45 -> 186.6558 | G45: 3234.345 | H45: =E45 -> -6.848 | I45: =F45 -> 186.6558 | J45: =H45 -> -6.848 | K45: =C45 -> 186.6558 | L45: =E45 -> -6.848
A46: E40 | B46: G16 | C46: 191.65558 | D46: 3237.58 | E46: =D46-MAX(D46:D93) -> -6.801 | F46: =C46+((C47-C46)/2) -> 194.15414 | G46: 3233.353 | H46: =E46 -> -6.801 | I46: =F46 -> 194.15414 | J46: =H46 -> -6.801 | K46: =C46 -> 191.65558 | L46: =E46 -> -6.801
A47: E41 | B47: G17 | C47: 196.65269 | D47: 3237.75 | E47: =D47-MAX(D47:D94) -> -6.631 | F47: =C47 -> 196.65269 | G47: 3232.508 | H47: =E47 -> -6.631 | I47: =F47 -> 196.65269 | J47: =H47 -> -6.631 | K47: =C47 -> 196.65269 | L47: =E47 -> -6.631
A48: E42 | B48: G18 | C48: 201.52815 | D48: 3238.859 | E48: =D48-MAX(D48:D95) -> -5.522 | F48: =C48+((C49-C48)/2) -> 204.02525 | G48: 3232.585 | H48: =E48 -> -5.522 | I48: =F48 -> 204.02525 | J48: =H48 -> -5.522 | K48: =C48 -> 201.52815 | L48: =E48 -> -5.522
A49: E43 | B49: G19 | C49: 206.52234 | D49: 3239.1 | E49: =D49-MAX(D49:D96) -> -5.281 | F49: =C49 -> 206.52234 | G49: 3230.417 | H49: =E49 -> -5.281 | I49: =F49 -> 206.52234 | J49: =H49 -> -5.281 | K49: =C49 -> 206.52234 | L49: =E49 -> -5.281
A50: E44 | B50: G20 | C50: 211.4902 | D50: 3239.666 | E50: =D50-MAX(D50:D97) -> -4.715 | F50: =C50+((C51-C50)/2) -> 213.98997 | G50: 3229.83 | H50: =E50 -> -4.715 | I50: =F50 -> 213.98997 | J50: =H50 -> -4.715 | K50: =C50 -> 211.4902 | L50: =E50 -> -4.715
A51: E45 | B51: G21 | C51: 216.48974 | D51: 3239.598 | E51: =D51-MAX(D51:D98) -> -4.783 | F51: =C51 -> 216.48974 | G51: 3231.088 | H51: =E51 -> -4.783 | I51: =F51 -> 216.48974 | J51: =H51 -> -4.783 | K51: =C51 -> 216.48974 | L51: =E51 -> -4.783
A52: E46 | B52: G22 | C52: 221.18165 | D52: 3241.326 | E52: =D52-MAX(D52:D99) -> -3.055 | F52: =C52+((C53-C52)/2) -> 223.53523 | G52: 3230.267 | H52: =E52 -> -3.055 | I52: =F52 -> 223.53523 | J52: =H52 -> -3.055 | K52: =C52 -> 221.18165 | L52: =E52 -> -3.055
...

Sheet GOL01_new
A1: Electrode | B1: x | C1: altitude | D1: x_rst | E1: altitude_rst | G1: x | H1: depth | I1: x | J1: depth | N1: RST_max | O1: =MAX(J24:J51) -> -7.158
A2: E1 | B2: 0 | C2: 3220.831 | G2: =B2 -> 0 | H2: =C2-MAX(C2:C49) -> -23.55 | N2: RST | Q2: ERT
A3: E2 | B3: 5 | C3: 3220.64 | G3: =B3 -> 5 | H3: =C3-MAX(C3:C50) -> -23.741 | N3: 112.5 | O3: -9.44 | Q3: =G2 -> 0 | R3: =H2-$O$1 -> -16.392
A4: E3 | B4: 10 | C4: 3220.57 | G4: =B4 -> 10 | H4: =C4-MAX(C4:C51) -> -23.811 | N4: 113.75 | O4: -9.14 | Q4: =G3 -> 5 | R4: =H3-$O$1 -> -16.583
A5: E4 | B5: 15 | C5: 3221.455 | G5: =B5 -> 15 | H5: =C5-MAX(C5:C52) -> -22.926 | N5: 115 | O5: -8.83 | Q5: =G4 -> 10 | R5: =H4-$O$1 -> -16.653
A6: E5 | B6: 20 | C6: 3221.27 | G6: =B6 -> 20 | H6: =C6-MAX(C6:C53) -> -23.111 | N6: 117.5 | O6: -8.71 | Q6: =G5 -> 15 | R6: =H5-$O$1 -> -15.768
A7: E6 | B7: 25 | C7: 3221.535 | G7: =B7 -> 25 | H7: =C7-MAX(C7:C54) -> -22.846 | N7: 120 | O7: -8.6 | Q7: =G6 -> 20 | R7: =H6-$O$1 -> -15.953
A8: E7 | B8: 30 | C8: 3222.111 | G8: =B8 -> 30 | H8: =C8-MAX(C8:C55) -> -22.27 | N8: 121.25 | O8: -8.3 | Q8: =G7 -> 25 | R8: =H7-$O$1 -> -15.688
A9: E8 | B9: 35 | C9: 3223.004 | G9: =B9 -> 35 | H9: =C9-MAX(C9:C56) -> -21.377 | N9: 122.5 | O9: -8.01 | Q9: =G8 -> 30 | R9: =H8-$O$1 -> -15.112
A10: E9 | B10: 40 | C10: 3224.328 | G10: =B10 -> 40 | H10: =C10-MAX(C10:C57) -> -20.053 | N10: 123.75 | O10: -7.72 | Q10: =G9 -> 35 | R10: =H9-$O$1 -> -14.219
A11: E10 | B11: 45 | C11: 3225.676 | G11: =B11 -> 45 | H11: =C11-MAX(C11:C58) -> -18.705 | N11: 125 | O11: -7.42 | Q11: =G10 -> 40 | R11: =H10-$O$1 -> -12.895
A12: E11 | B12: 50 | C12: 3225.607 | G12: =B12 -> 50 | H12: =C12-MAX(C12:C59) -> -18.774 | N12: 126.25 | O12: -7.31 | Q12: =G11 -> 45 | R12: =H11-$O$1 -> -11.547
A13: E12 | B13: 55 | C13: 3225.707 | G13: =B13 -> 55 | H13: =C13-MAX(C13:C60) -> -18.674 | N13: 127.5 | O13: -7.19 | Q13: =G12 -> 50 | R13: =H12-$O$1 -> -11.616
A14: E13 | B14: 60 | C14: 3224.435 | G14: =B14 -> 60 | H14: =C14-MAX(C14:C61) -> -19.946 | N14: 128.75 | O14: -7.07 | Q14: =G13 -> 55 | R14: =H13-$O$1 -> -11.516
... A23: E22 | B23: 105 | C23: 3226.33 | G23: =B23 -> 105 | H23: =C23-MAX(C23:C70) -> -18.051 | N23: 140 | O23: -7.39 | Q23: =G22 -> 100 | R23: =H22-$O$1 -> -10.83
A24: E23 | B24: 110 | C24: 3227.329 | G24: =B24 -> 110 | H24: =C24-MAX(C24:C71) -> -17.052 | I24: 112.5 | J24: -16.6 | N24: 141.25 | O24: -7.24 | Q24: =G23 -> 105 | R24: =H23-$O$1 -> -10.893
A25: E24 | B25: 115 | C25: 3228.389 | G25: =B25 -> 115 | H25: =C25-MAX(C25:C72) -> -15.992 | I25: 115 | J25: =H25 -> -15.992 | N25: 142.5 | O25: -7.1 | Q25: =G24 -> 110 | R25: =H24-$O$1 -> -9.894
A26: E25 | B26: 120 | C26: 3228.625 | D26: =B26+0 -> 120 | E26: 3235.891 | F26: =C26 -> 3228.625 | G26: =B26 -> 120 | H26: =C26-MAX(C26:C73) -> -15.756 | I26: =D26 -> 120 | J26: =F26-MAX(C2:C49) -> -15.756 | N26: 143.75 | O26: -6.95 | Q26: =G25 -> 115 | R26: =H25-$O$1 -> -8.834
A27: E26 | B27: 125 | C27: 3229.798 | D27: =D26+2.5 -> 122.5 | E27: 3236.373 | F27: =(F26+F28)/2 -> 3229.2115 | G27: =B27 -> 125 | H27: =C27-MAX(C27:C74) -> -14.583 | I27: =D27 -> 122.5 | J27: =F27-MAX(C3:C50) -> -15.1695 | N27: 145 | O27: -6.8 | Q27: =G26 -> 120 | R27: =H26-$O$1 -> -8.598
A28: E27 | B28: 130 | C28: 3230.267 | D28: =D27+2.5 -> 125 | E28: 3236.855 | F28: =C27 -> 3229.798 | G28: =B28 -> 130 | H28: =C28-MAX(C28:C75) -> -14.114 | I28: =D28 -> 125 | J28: =F28-MAX(C4:C51) -> -14.583 | N28: 146.25 | O28: -6.26 | Q28: =G27 -> 125 | R28: =H27-$O$1 -> -7.425
A29: E28 | B29: 135 | C29: 3231.088 | D29: =D28+2.5 -> 127.5 | E29: 3237.135 | F29: =(F28+F30)/2 -> 3230.0325 | G29: =B29 -> 135 | H29: =C29-MAX(C29:C76) -> -13.293 | I29: =D29 -> 127.5 | J29: =F29-MAX(C5:C52) -> -14.3485 | N29: 147.5 | O29: -5.72 | Q29: =G28 -> 130 | R29: =H28-$O$1 -> -6.956
A30: E29 | B30: 140 | C30: 3229.83 | D30: =D29+2.5 -> 130 | E30: 3237.753 | F30: =C28 -> 3230.267 | G30: =B30 -> 140 | H30: =C30-MAX(C30:C77) -> -14.551 | I30: =D30 -> 130 | J30: =F30-MAX(C6:C53) -> -14.114 | N30: 148.75 | O30: -5.18 | Q30: =G29 -> 135 | R30: -6.25
A31: E30 | B31: 145 | C31: 3230.417 | D31: =D30+2.5 -> 132.5 | E31: 3237.924 | F31: =(F30+F32)/2 -> 3230.6775 | G31: =B31 -> 145 | H31: =C31-MAX(C31:C78) -> -13.964 | I31: =D31 -> 132.5 | J31: =F31-MAX(C7:C54) -> -13.7035 | N31: 150 | O31: -4.64 | Q31: =G30 -> 140 | R31: =H30-$O$1 -> -7.393
A32: E31 | B32: 150 | C32: 3232.585 | D32: =D31+2.5 -> 135 | E32: 3238.009 | F32: =C29 -> 3231.088 | G32: =B32 -> 150 | H32: =C32-MAX(C32:C79) -> -11.796 | I32: =D32 -> 135 | J32: =F32-MAX(C8:C55) -> -13.293 | N32: 151.25 | O32: -4.66 | Q32: =G31 -> 145 | R32: =H31-$O$1 -> -6.806
A33: E32 | B33: 155 | C33: 3232.508 | D33: =D32+2.5 -> 137.5 | E33: 3237.699 | F33: =(F32+F34)/2 -> 3230.459 | G33: =B33 -> 155 | H33: =C33-MAX(C33:C80) -> -11.873 | I33: =D33 -> 137.5 | J33: =F33-MAX(C9:C56) -> -13.922 | N33: 152.5 | O33: -4.67 | Q33: =G32 -> 150 | R33: =H32-$O$1 -> -4.638
A34: E33 | B34: 160 | C34: 3233.353 | D34: =D33+2.5 -> 140 | E34: 3237.218 | F34: =C30 -> 3229.83 | G34: =B34 -> 160 | H34: =C34-MAX(C34:C81) -> -11.028 | I34: =D34 -> 140 | J34: =F34-MAX(C10:C57) -> -14.551 | N34: 153.75 | O34: -4.69 | Q34: =G33 -> 155 | R34: =H33-$O$1 -> -4.715
A35: E34 | B35: 165 | C35: 3234.345 | D35: =D34+2.5 -> 142.5 | E35: 3237.592 | F35: =(F34+F36)/2 -> 3230.1235 | G35: =B35 -> 165 | H35: =C35-MAX(C35:C82) -> -10.036 | I35: =D35 -> 142.5 | J35: =F35-MAX(C11:C58) -> -14.2575 | N35: 155 | O35: -4.71 | Q35: =G34 -> 160 | R35: =H34-$O$1 -> -3.87
A36: E35 | B36: 170 | C36: 3234.74 | D36: =D35+2.5 -> 145 | E36: 3238.583 | F36: =C31 -> 3230.417 | G36: =B36 -> 170 | H36: =C36-MAX(C36:C83) -> -9.641 | I36: =D36 -> 145 | J36: =F36-MAX(C12:C59) -> -13.964 | N36: 156.25 | O36: -4.5 | Q36: =G35 -> 165 | R36: =H35-$O$1 -> -2.878
A37: E36 | B37: 175 | C37: 3236.006 | D37: =D36+2.5 -> 147.5 | E37: 3239.069 | F37: =(F36+F38)/2 -> 3231.501 | G37: =B37 -> 175 | H37: =C37-MAX(C37:C84) -> -8.375 | I37: =D37 -> 147.5 | J37: =F37-MAX(C13:C60) -> -12.88 | N37: 157.5 | O37: -4.29 | Q37: =G36 -> 170 | R37: =H36-$O$1 -> -2.483
A38: E37 | B38: 180 | C38: 3236.129 | D38: =D37+2.5 -> 150 | E38: 3239.015 | F38: =C32 -> 3232.585 | G38: =B38 -> 180 | H38: =C38-MAX(C38:C85) -> -8.252 | I38: =D38 -> 150 | J38: =F38-MAX(C14:C61) -> -11.796 | N38: 158.75 | O38: -4.08 | Q38: =G37 -> 175 | R38: =H37-$O$1 -> -1.217
A39: E38 | B39: 185 | C39: 3237.223 | D39: =D38+2.5 -> 152.5 | E39: 3239.221 | F39: =(F38+F40)/2 -> 3232.5465 | G39: =B39 -> 185 | H39: =C39-MAX(C39:C86) -> -7.158 | I39: =D39 -> 152.5 | J39: =F39-MAX(C15:C62) -> -11.8345 | N39: 160 | O39: -3.87 | Q39: =G38 -> 180 | R39: =H38-$O$1 -> -1.094
A40: E39 | B40: 190 | C40: 3237.533 | D40: =D39+2.5 -> 155 | E40: 3239.696 | F40: =C33 -> 3232.508 | G40: =B40 -> 190 | H40: =C40-MAX(C40:C87) -> -6.848 | I40: =D40 -> 155 | J40: =F40-MAX(C16:C63) -> -11.873 | N40: 161.25 | O40: -3.62 | Q40: =G39 -> 185 | R40: =H39-$O$1 -> 0
A41: E40 | B41: 195 | C41: 3237.58 | D41: =D40+2.5 -> 157.5 | E41: 3239.792 | F41: =(F40+F42)/2 -> 3232.9305 | G41: =B41 -> 195 | H41: =C41-MAX(C41:C88) -> -6.801 | I41: =D41 -> 157.5 | J41: =F41-MAX(C17:C64) -> -11.4505 | N41: 162.5 | O41: -3.37 | Q41: =G40 -> 190 | R41: =H40-$O$1 -> 0.31
A42: E41 | B42: 200 | C42: 3237.75 | D42: =D41+2.5 -> 160 | E42: 3239.912 | F42: =C34 -> 3233.353 | G42: =B42 -> 200 | H42: =C42-MAX(C42:C89) -> -6.631 | I42: =D42 -> 160 | J42: =F42-MAX(C18:C65) -> -11.028 | N42: 163.75 | O42: -3.12 | Q42: =G41 -> 195 | R42: =H41-$O$1 -> 0.357
A43: E42 | B43: 205 | C43: 3238.859 | D43: =D42+2.5 -> 162.5 | E43: 3240.366 | F43: =(F42+F44)/2 -> 3233.849 | G43: =B43 -> 205 | H43: =C43-MAX(C43:C90) -> -5.522 | I43: =D43 -> 162.5 | J43: =F43-MAX(C19:C66) -> -10.532 | N43: 165 | O43: -2.88 | Q43: =G42 -> 200 | R43: =H42-$O$1 -> 0.527
A44: E43 | B44: 210 | C44: 3239.1 | D44: =D43+2.5 -> 165 | E44: 3240.169 | F44: =C35 -> 3234.345 | G44: =B44 -> 210 | H44: =C44-MAX(C44:C91) -> -5.281 | I44: =D44 -> 165 | J44: =F44-MAX(C20:C67) -> -10.036 | N44: 166.25 | O44: -2.78 | Q44: =G43 -> 205 | R44: =H43-$O$1 -> 1.636
A45: E44 | B45: 215 | C45: 3239.666 | D45: =D44+2.5 -> 167.5 | E45: 3241.697 | F45: =(F44+F46)/2 -> 3234.5425 | G45: =B45 -> 215 | H45: =C45-MAX(C45:C92) -> -4.715 | I45: =D45 -> 167.5 | J45: =F45-MAX(C21:C68) -> -9.8385 | N45: 167.5 | O45: -2.68 | Q45: =G44 -> 210 | R45: =H44-$O$1 -> 1.877
A46: E45 | B46: 220 | C46: 3239.598 | D46: =D45+2.5 -> 170 | E46: 3242.205 | F46: =C36 -> 3234.74 | G46: =B46 -> 220 | H46: =C46-MAX(C46:C93) -> -4.783 | I46: =D46 -> 170 | J46: =F46-MAX(C22:C69) -> -9.641 | N46: 168.75 | O46: -2.58 | Q46: =G45 -> 215 | R46: =H45-$O$1 -> 2.443
A47: E46 | B47: 225 | C47: 3241.326 | D47: =D46+2.5 -> 172.5 | E47: 3242.903 | F47: =(F46+F48)/2 -> 3235.373 | G47: =B47 -> 225 | H47: =C47-MAX(C47:C94) -> -3.055 | I47: =D47 -> 172.5 | J47: =F47-MAX(C23:C70) -> -9.008 | N47: 170 | O47: -2.48 | Q47: =G46 -> 220 | R47: =H46-$O$1 -> 2.375
A48: E47 | B48: 230 | C48: 3243.012 | D48: =D47+2.5 -> 175 | E48: 3243.705 | F48: =C37 -> 3236.006 | G48: =B48 -> 230 | H48: =C48-MAX(C48:C95) -> -1.369 | I48: =D48 -> 175 | J48: =F48-MAX(C24:C71) -> -8.375 | N48: 171.25 | O48: -2.16 | Q48: =G47 -> 225 | R48: =H47-$O$1 -> 4.103
...

Sheet GOL07ab
A1: GOL07ab | C1: G1 = E1 | T1: RST_max = 0 | V1: RST_max = | W1: =MAX(K5:K48) -> 0
C3: ERT (original) | G3: RST | J3: RST (new) | T3: RST smooth | W3: ERT smooth
A4: #ERT | B4: #GST | C4: x | D4: z | E4: x | F4: z_depth | G4: x | H4: z_alt | I4: z_depth | J4: x | K4: z | O4: GOL07a only | Q4: GOL07b only
H5: -7.5 | I5: 0 | J5: =H5 -> -7.5 | K5: =I5 -> 0 | L5: -7.5 | M5: 3192.405 | N5: =M5-D6 -> 0 | O5: -7.5 | P5: =K5 -> 0 | T5: =J5 -> -7.5 | U5: =K5 -> 0
A6: E1 | B6: G1 | C6: 0 | D6: =M5 -> 3192.405 | E6: =C6 -> 0 | F6: =D6-MAX($D$6:$D$125) -> 0 | G6: =D6 -> 3192.405 | H6: =C6 -> 0 | I6: =F6 -> 0 | J6: =H6 -> 0 | K6: =I6 -> 0 | L6: 0 | M6: 3192.405 | N6: =M6-D7 -> 0 | O6: 0 | P6: =K6 -> 0 | T6: =J6 -> 0 | U6: =K6 -> 0 | W6: 0 | X6: 0
A7: E2 | B7: G2 | C7: 4.9555802 | D7: =M6 -> 3192.405 | E7: =C7 -> 4.9555802 | F7: =D7-MAX($D$6:$D$125) -> 0 | G7: =D7 -> 3192.405 | H7: =C7 -> 4.9555802 | I7: =F7 -> 0 | J7: =H7 -> 4.9555802 | K7: =I7 -> 0 | L7: 5 | M7: 3191.74 | N7: =M7-D8 -> 0 | O7: 5 | P7: =K7 -> 0 | T7: =J7 -> 4.9555802 | U7: =K7 -> 0 | W7: 4.9555802 | X7: 0
A8: E3 | B8: G3 | C8: 9.9518152 | D8: =M7 -> 3191.74 | E8: =C8 -> 9.9518152 | F8: =D8-MAX($D$6:$D$125) -> -0.665 | G8: =D8 -> 3191.74 | H8: =C8 -> 9.9518152 | I8: =F8 -> -0.665 | J8: =H8 -> 9.9518152 | K8: =I8 -> -0.665 | L8: 10 | M8: 3191.546 | N8: =M8-D9 -> 0 | O8: 10 | P8: =K8 -> -0.665 | T8: =J8 -> 9.9518152 | U8: =K8 -> -0.665 | W8: 9.9518152 | X8: -0.665
A9: E4 | B9: G4 | C9: 14.951814 | D9: =M8 -> 3191.546 | E9: =C9 -> 14.951814 | F9: =D9-MAX($D$6:$D$125) -> -0.859 | G9: =D9 -> 3191.546 | H9: =C9 -> 14.951814 | I9: =F9 -> -0.859 | J9: =H9 -> 14.951814 | K9: =I9 -> -0.859 | L9: 15 | M9: 3191.55 | N9: =M9-D10 -> 0 | O9: 15 | P9: =K9 -> -0.859 | T9: =J9 -> 14.951814 | U9: =K9 -> -0.859 | W9: 14.951814 | X9: -0.859
A10: E5 | B10: G5 | C10: 19.664324 | D10: =M9 -> 3191.55 | E10: =C10 -> 19.664324 | F10: =D10-MAX($D$6:$D$125) -> -0.855 | G10: =D10 -> 3191.55 | H10: =C10 -> 19.664324 | I10: =F10 -> -0.855 | J10: =H10 -> 19.664324 | K10: =I10 -> -0.855 | L10: 19.7 | M10: 3189.879 | N10: =M10-D11 -> 0 | O10: 20 | P10: =K10 -> -0.855 | T10: =J10 -> 19.664324 | U10: =K10 -> -0.855 | W10: 19.664324 | X10: -0.855
A11: E6 | B11: G6 | C11: 24.620972 | D11: =M10 -> 3189.879 | E11: =C11 -> 24.620972 | F11: =D11-MAX($D$6:$D$125) -> -2.526 | G11: =D11 -> 3189.879 | H11: =C11 -> 24.620972 | I11: =F11 -> -2.526 | J11: =H11 -> 24.620972 | K11: =I11 -> -2.526 | L11: 24.6 | M11: 3190.536 | N11: =M11-D12 -> 0 | O11: 25 | P11: =K11 -> -2.526 | T11: =J11 -> 24.620972 | U11: =-1.5 -> -1.5 | W11: 24.620972 | X11: -1.5
A12: E7 | B12: G7 | C12: 29.605894 | D12: =M11 -> 3190.536 | E12: =C12 -> 29.605894 | F12: =D12-MAX($D$6:$D$125) -> -1.869 | G12: =D12 -> 3190.536 | H12: =C12 -> 29.605894 | I12: =F12 -> -1.869 | J12: =H12 -> 29.605894 | K12: =I12 -> -1.869 | L12: 29.6 | M12: 3190.148 | N12: =M12-D13 -> 0 | O12: 30 | P12: =K12 -> -1.869 | T12: =J12 -> 29.605894 | U12: =K12 -> -1.869 | W12: 29.605894 | X12: -1.869
A13: E8 | B13: G8 | C13: 34.277943 | D13: =M12 -> 3190.148 | E13: =C13 -> 34.277943 | F13: =D13-MAX($D$6:$D$125) -> -2.257 | G13: =D13 -> 3190.148 | H13: =C13 -> 34.277943 | I13: =F13 -> -2.257 | J13: =H13 -> 34.277943 | K13: =I13 -> -2.257 | L13: 34.3 | M13: 3188.367 | N13: =M13-D14 -> 0 | O13: 35 | P13: =K13 -> -2.257 | T13: =J13 -> 34.277943 | U13: =K13 -> -2.257 | W13: 34.277943 | X13: -2.257
A14: E9 | B14: G9 | C14: 39.271231 | D14: =M13 -> 3188.367 | E14: =C14 -> 39.271231 | F14: =D14-MAX($D$6:$D$125) -> -4.038 | G14: =D14 -> 3188.367 | H14: =C14 -> 39.271231 | I14: =F14 -> -4.038 | J14: =H14 -> 39.271231 | K14: =I14 -> -4.038 | L14: 39.3 | M14: 3188.108 | N14: =M14-D15 -> 0 | O14: 40 | P14: =K14 -> -4.038 | T14: =J14 -> 39.271231 | U14: -3.2 | W14: 39.271231 | X14: -3.2
A15: E10 | B15: G10 | C15: 44.25021 | D15: =M14 -> 3188.108 | E15: =C15 -> 44.25021 | F15: =D15-MAX($D$6:$D$125) -> -4.297 | G15: =D15 -> 3188.108 | H15: =C15 -> 44.25021 | I15: =F15 -> -4.297 | J15: =H15 -> 44.25021 | K15: =I15 -> -4.297 | L15: 44.3 | M15: 3187.65 | N15: =M15-D16 -> 0 | O15: 45 | P15: =K15 -> -4.297 | T15: =J15 -> 44.25021 | U15: =K15 -> -4.297 | W15: 44.25021 | X15: -4.297
A16: E11 | B16: G11 | C16: 49.232791 | D16: =M15 -> 3187.65 | E16: =C16 -> 49.232791 | F16: =D16-MAX($D$6:$D$125) -> -4.755 | G16: =D16 -> 3187.65 | H16: =C16 -> 49.232791 | I16: =F16 -> -4.755 | J16: =H16 -> 49.232791 | K16: =I16 -> -4.755 | L16: 49.2 | M16: 3187.233 | N16: =M16-D17 -> 0 | O16: 50 | P16: =K16 -> -4.755 | T16: =J16 -> 49.232791 | U16: =K16 -> -4.755 | W16: 49.232791 | X16: -4.755
A17: E12 | B17: G12 | C17: 54.225332 | D17: =M16 -> 3187.233 | E17: =C17 -> 54.225332 | F17: =D17-MAX($D$6:$D$125) -> -5.172 | G17: =D17 -> 3187.233 | H17: =C17 -> 54.225332 | I17: =F17 -> -5.172 | J17: =H17 -> 54.225332 | K17: =I17 -> -5.172 | L17: 54.2 | M17: 3187.506 | N17: =M17-D18 -> 0 | O17: 55 | P17: =K17 -> -5.172 | T17: =J17 -> 54.225332 | U17: =K17 -> -5.172 | W17: 54.225332 | X17: -5.172
