Workbook

Sheet all
A1: ID | B1: LON | C1: LAT | D1: HEIGHT | E1: LABEL
A2: GOL01_01 | B2: 74.486576 | C2: 42.479419 | D2: 3244.381 | E2: GOL01
A3: GOL01_02 | B3: 74.486538 | C3: 42.479448 | D3: 3243.012
A4: GOL01_03 | B4: 74.48649 | C4: 42.479475 | D4: 3241.326
A5: GOL01_04 | B5: 74.486452 | C5: 42.479502 | D5: 3239.598
A6: GOL01_05 | B6: 74.486404 | C6: 42.479528 | D6: 3239.666
A7: GOL01_06 | B7: 74.486359 | C7: 42.479558 | D7: 3239.1
A8: GOL01_07 | B8: 74.486319 | C8: 42.479587 | D8: 3238.859
A9: GOL01_08 | B9: 74.486273 | C9: 42.479616 | D9: 3237.75
A10: GOL01_09 | B10: 74.486223 | C10: 42.479644 | D10: 3237.58
A11: GOL01_10 | B11: 74.486188 | C11: 42.479675 | D11: 3237.533
A12: GOL01_11 | B12: 74.486143 | C12: 42.479706 | D12: 3237.223
A13: GOL01_12 | B13: 74.4861 | C13: 42.479735 | D13: 3236.129
A14: GOL01_13 | B14: 74.486058 | C14: 42.479763 | D14: 3236.006
... A49: GOL01_48 | B49: 74.48451 | C49: 42.480777 | D49: 3220.831
A50: GOL05_01 | B50: 74.486646 | C50: 42.476835 | D50: 3399.292 | E50: GOL05
A51: GOL05_02 | B51: 74.486673 | C51: 42.476796 | D51: 3398.924
A52: GOL05_03 | B52: 74.48671 | C52: 42.47676 | D52: 3398.107
A53: GOL05_04 | B53: 74.486743 | C53: 42.476723 | D53: 3396.931
A54: GOL05_05 | B54: 74.486777 | C54: 42.476687 | D54: 3396.416
A55: GOL05_06 | B55: 74.486809 | C55: 42.476652 | D55: 3396.554
A56: GOL05_07 | B56: 74.486848 | C56: 42.476618 | D56: 3397.082
A57: GOL05_08 | B57: 74.486877 | C57: 42.476574 | D57: 3397.918
A58: GOL05_09 | B58: 74.48691 | C58: 42.476539 | D58: 3398.55
A59: GOL05_10 | B59: 74.486944 | C59: 42.476502 | D59: 3399.138
A60: GOL05_11 | B60: 74.486976 | C60: 42.476469 | D60: 3399.95
A61: GOL05_12 | B61: 74.487008 | C61: 42.476426 | D61: 3400.837
A62: GOL05_13 | B62: 74.487037 | C62: 42.476391 | D62: 3401.534
... A97: GOL05_48 | B97: 74.488144 | C97: 42.475073 | D97: 3420.621
A98: GOL06_01 | B98: 74.489797 | C98: 42.479998 | D98: 3212.296 | E98: GOL06
A99: GOL06_02 | B99: 74.489815 | C99: 42.480017 | D99: 3211.804
A100: GOL06_03 | B100: 74.489852 | C100: 42.480054 | D100: 3210.055
A101: GOL06_04 | B101: 74.489882 | C101: 42.480088 | D101: 3208.605
A102: GOL06_05 | B102: 74.489919 | C102: 42.480123 | D102: 3207.222
A103: GOL06_06 | B103: 74.489946 | C103: 42.480163 | D103: 3205.554
A104: GOL06_07 | B104: 74.48997 | C104: 42.480201 | D104: 3204.301
A105: GOL06_08 | B105: 74.489993 | C105: 42.480236 | D105: 3202.629
A106: GOL06_09 | B106: 74.490027 | C106: 42.480285 | D106: 3201.624
A107: GOL06_10 | B107: 74.490042 | C107: 42.480317 | D107: 3200.39
A108: GOL06_11 | B108: 74.490077 | C108: 42.480349 | D108: 3199.252
...

Sheet GOL01
A1: Name | B1: Easting | C1: Northing | D1: Elevation | E1: Description | F1: Longitude | G1: Latitude | H1: Ellipsoidal height | I1: Easting RMS | J1: Northing RMS | K1: Elevation RMS | L1: Lateral RMS | M1: Antenna height | N1: Antenna height units | O1: Solution status | P1: Averaging start | Q1: Averaging end | R1: Samples | S1: PDOP | T1: Base easting | U1: Base northing | V1: Base elevation | W1: Base longitude | X1: Base latitude | Y1: Base ellipsoidal height | Z1: Baseline | AA1: CS name
A2: 1 | E2: E48 | F2: 74.486576 | G2: 42.479419 | H2: 3244.381 | I2: 0.01 | J2: 0.011 | K2: 0.012 | L2: 0.015 | M2: 2.134 | N2: m | O2: FIX | P2: 2022-08-07 10:35:36.3 UTC+06:00 | Q2: 2022-08-07 10:35:42.3 UTC+06:00 | R2: 7 | S2: 1.5 | W2: 74.486221 | X2: 42.48117 | Y2: 3210.508 | Z2: 200.077 | AA2: Global CS
A3: 2 | E3: E47 | F3: 74.486538 | G3: 42.479448 | H3: 3243.012 | I3: 0.013 | J3: 0.015 | K3: 0.013 | L3: 0.019 | M3: 2.134 | N3: m | O3: FIX | P3: 2022-08-07 10:36:15.3 UTC+06:00 | Q3: 2022-08-07 10:36:20.3 UTC+06:00 | R3: 6 | S3: 1.4 | W3: 74.486221 | X3: 42.48117 | Y3: 3210.508 | Z3: 196.178 | AA3: Global CS
A4: 3 | E4: E46 | F4: 74.48649 | G4: 42.479475 | H4: 3241.326 | I4: 0.012 | J4: 0.012 | K4: 0.011 | L4: 0.017 | M4: 2.134 | N4: m | O4: FIX | P4: 2022-08-07 10:36:54.3 UTC+06:00 | Q4: 2022-08-07 10:36:59.3 UTC+06:00 | R4: 6 | S4: 1.4 | W4: 74.486221 | X4: 42.48117 | Y4: 3210.508 | Z4: 192.44 | AA4: Global CS
A5: 4 | E5: E45 | F5: 74.486452 | G5: 42.479502 | H5: 3239.598 | I5: 0.011 | J5: 0.01 | K5: 0.01 | L5: 0.015 | M5: 2.134 | N5: m | O5: FIX | P5: 2022-08-07 10:37:47.3 UTC+06:00 | Q5: 2022-08-07 10:37:53.3 UTC+06:00 | R5: 7 | S5: 1.4 | W5: 74.486221 | X5: 42.48117 | Y5: 3210.508 | Z5: 188.88 | AA5: Global CS
A6: 5 | E6: E44 | F6: 74.486404 | G6: 42.479528 | H6: 3239.666 | I6: 0.011 | J6: 0.011 | K6: 0.01 | L6: 0.015 | M6: 2.134 | N6: m | O6: FIX | P6: 2022-08-07 10:38:21.3 UTC+06:00 | Q6: 2022-08-07 10:38:26.4 UTC+06:00 | R6: 6 | S6: 1.4 | W6: 74.486221 | X6: 42.48117 | Y6: 3210.508 | Z6: 185.783 | AA6: Global CS
A7: 6 | E7: E43 | F7: 74.486359 | G7: 42.479558 | H7: 3239.1 | I7: 0.012 | J7: 0.012 | K7: 0.016 | L7: 0.017 | M7: 2.134 | N7: m | O7: FIX | P7: 2022-08-07 10:38:58.3 UTC+06:00 | Q7: 2022-08-07 10:39:03.3 UTC+06:00 | R7: 6 | S7: 1.4 | W7: 74.486221 | X7: 42.48117 | Y7: 3210.508 | Z7: 182.052 | AA7: Global CS
A8: 7 | E8: E42 | F8: 74.486319 | G8: 42.479587 | H8: 3238.859 | I8: 0.012 | J8: 0.018 | K8: 0.018 | L8: 0.021 | M8: 2.134 | N8: m | O8: FIX | P8: 2022-08-07 10:39:27.3 UTC+06:00 | Q8: 2022-08-07 10:39:32.4 UTC+06:00 | R8: 6 | S8: 1.4 | W8: 74.486221 | X8: 42.48117 | Y8: 3210.508 | Z8: 178.753 | AA8: Global CS
A9: 8 | E9: E41 | F9: 74.486273 | G9: 42.479616 | H9: 3237.75 | I9: 0.011 | J9: 0.01 | K9: 0.012 | L9: 0.015 | M9: 2.134 | N9: m | O9: FIX | P9: 2022-08-07 10:40:26.4 UTC+06:00 | Q9: 2022-08-07 10:40:31.4 UTC+06:00 | R9: 6 | S9: 1.4 | W9: 74.486221 | X9: 42.48117 | Y9: 3210.508 | Z9: 175.218 | AA9: Global CS
A10: 9 | E10: E40 | F10: 74.486223 | G10: 42.479644 | H10: 3237.58 | I10: 0.011 | J10: 0.012 | K10: 0.011 | L10: 0.016 | M10: 2.134 | N10: m | O10: FIX | P10: 2022-08-07 10:40:54.3 UTC+06:00 | Q10: 2022-08-07 10:40:59.4 UTC+06:00 | R10: 6 | S10: 1.4 | W10: 74.486221 | X10: 42.48117 | Y10: 3210.508 | Z10: 172.103 | AA10: Global CS
A11: 10 | E11: E39 | F11: 74.486188 | G11: 42.479675 | H11: 3237.533 | I11: 0.011 | J11: 0.012 | K11: 0.01 | L11: 0.017 | M11: 2.134 | N11: m | O11: FIX | P11: 2022-08-07 10:41:20.3 UTC+06:00 | Q11: 2022-08-07 10:41:25.4 UTC+06:00 | R11: 6 | S11: 1.4 | W11: 74.486221 | X11: 42.48117 | Y11: 3210.508 | Z11: 168.672 | AA11: Global CS
A12: 11 | E12: E38 | F12: 74.486143 | G12: 42.479706 | H12: 3237.223 | I12: 0.011 | J12: 0.011 | K12: 0.011 | L12: 0.015 | M12: 2.134 | N12: m | O12: FIX | P12: 2022-08-07 10:41:42.4 UTC+06:00 | Q12: 2022-08-07 10:41:48.4 UTC+06:00 | R12: 7 | S12: 1.4 | W12: 74.486221 | X12: 42.48117 | Y12: 3210.508 | Z12: 165.407 | AA12: Global CS
A13: 12 | E13: E37 | F13: 74.4861 | G13: 42.479735 | H13: 3236.129 | I13: 0.014 | J13: 0.012 | K13: 0.011 | L13: 0.019 | M13: 2.134 | N13: m | O13: FIX | P13: 2022-08-07 10:42:08.4 UTC+06:00 | Q13: 2022-08-07 10:42:14.4 UTC+06:00 | R13: 7 | S13: 1.4 | W13: 74.486221 | X13: 42.48117 | Y13: 3210.508 | Z13: 162.233 | AA13: Global CS
... A49: 48 | E49: E1 | F49: 74.48451 | G49: 42.480777 | H49: 3220.831 | I49: 0.013 | J49: 0.011 | K49: 0.011 | L49: 0.017 | M49: 2.134 | N49: m | O49: FIX | P49: 2022-08-07 11:00:51.4 UTC+06:00 | Q49: 2022-08-07 11:00:56.4 UTC+06:00 | R49: 6 | S49: 1.4 | W49: 74.486221 | X49: 42.48117 | Y49: 3210.508 | Z49: 147.884 | AA49: Global CS

Sheet GOL01_RST
A1: Name | B1: x | C1: z | D1: RST Topo | F1: Reflex W | H1: Pygimli | J1: Pygimli ture horizontal | M1: Name | N1: x | O1: z | P1: RST Topo | R1: Reflex W | T1: Pygimli | V1: Pygimli ture horizontal
A3: OFF1 | B3: 992.5 | C3: 3228.625 | D3: =B3 -> 992.5 | E3: =ABS(C3-MAX(C:C))+0.01 -> 15.766 | H3: =B3-1000 -> -7.5 | I3: =C3 -> 3228.625 | J3: =H3 -> -7.5 | K3: =C60 -> 3227.329 | M3: OFF1 | N3: 992.5 | O3: 3228.625 | P3: =N3 -> 992.5 | Q3: =ABS(O3-MAX(O:O))+0.01 -> 15.766 | T3: =T5-7.5 -> 112.5 | U3: =O3 -> 3228.625 | V3: =T3 -> 112.5 | W3: 3245.881
A4: OFF2 | B4: 997.5 | C4: 3228.625 | D4: 997.5 | E4: =ABS(C4-MAX(C:C))+0.01 -> 15.766 | F4: 0 | G4: 0 | H4: =B4-1000 -> -2.5 | I4: =C4 -> 3228.625 | J4: =H4 -> -2.5 | K4: =C61 -> 3228.389 | M4: OFF2 | N4: 997.5 | O4: 3228.625 | P4: 997.5 | Q4: =ABS(O4-MAX(O:O))+0.01 -> 15.766 | R4: 0 | S4: 0 | T4: =T5-2.5 -> 117.5 | U4: =O4 -> 3228.625 | V4: =T4 -> 117.5 | W4: 3244.881
A5: G1 | B5: 1000 | C5: 3228.625 | D5: =B5 -> 1000 | E5: =ABS(C5-MAX(C:C))+0.01 -> 15.766 | F5: =D5 -> 1000 | G5: =E5 -> 15.766 | H5: =B5-1000 -> 0 | I5: =C5 -> 3228.625 | J5: =D5-1000 -> 0 | K5: =C62 -> 3228.625 | M5: G1 | N5: 1120 | O5: 3228.625 | P5: =N5 -> 1120 | Q5: =ABS(O5-MAX(O:O))+0.01 -> 15.766 | R5: =P5 -> 1120 | S5: =Q5 -> 15.766 | T5: =N5-1000 -> 120 | U5: =O5 -> 3228.625 | V5: =P5-1000 -> 120 | W5: 3244.381
A6: G2 | B6: =B5+2.5 -> 1002.5 | C6: 3229.798 | D6: =D5+(SQRT((B6-B5)^2-(E6-E5)^2)) -> 1002.2077 | E6: =ABS(C6-MAX(C:C))+0.01 -> 14.593 | F6: =D6 -> 1002.2077 | G6: =E6 -> 14.593 | H6: =B6-1000 -> 2.5 | I6: =C6 -> 3229.798 | J6: =D6-1000 -> 2.2077298 | K6: =C63 -> 3229.798 | M6: G2 | N6: =N5+2.5 -> 1122.5 | O6: 3229.798 | P6: =P5+(SQRT((N6-N5)^2-(Q6-Q5)^2)) -> 1122.2077 | Q6: =ABS(O6-MAX(O:O))+0.01 -> 14.593 | R6: =P6 -> 1122.2077 | S6: =Q6 -> 14.593 | T6: =N6-1000 -> 122.5 | U6: =O6 -> 3229.798 | V6: =P6-1000 -> 122.20773 | W6: 3243.012
A7: G3 | B7: =B6+2.5 -> 1005 | C7: 3230.267 | D7: =D6+(SQRT((B7-B6)^2-(E7-E6)^2)) -> 1004.6633 | E7: =ABS(C7-MAX(C:C))+0.01 -> 14.124 | F7: =D7 -> 1004.6633 | G7: =E7 -> 14.124 | H7: =B7-1000 -> 5 | I7: =C7 -> 3230.267 | J7: =D7-1000 -> 4.6633436 | K7: =C64 -> 3230.267 | M7: G3 | N7: =N6+2.5 -> 1125 | O7: 3230.267 | P7: =P6+(SQRT((N7-N6)^2-(Q7-Q6)^2)) -> 1124.6633 | Q7: =ABS(O7-MAX(O:O))+0.01 -> 14.124 | R7: =P7 -> 1124.6633 | S7: =Q7 -> 14.124 | T7: =N7-1000 -> 125 | U7: =O7 -> 3230.267 | V7: =P7-1000 -> 124.66334 | W7: 3241.326
A8: G4 | B8: =B7+2.5 -> 1007.5 | C8: 3231.088 | D8: =D7+(SQRT((B8-B7)^2-(E8-E7)^2)) -> 1007.0247 | E8: =ABS(C8-MAX(C:C))+0.01 -> 13.303 | F8: =D8 -> 1007.0247 | G8: =E8 -> 13.303 | H8: =B8-1000 -> 7.5 | I8: =C8 -> 3231.088 | J8: =D8-1000 -> 7.0246905 | K8: =C65 -> 3231.088 | M8: G4 | N8: =N7+2.5 -> 1127.5 | O8: 3231.088 | P8: =P7+(SQRT((N8-N7)^2-(Q8-Q7)^2)) -> 1127.0247 | Q8: =ABS(O8-MAX(O:O))+0.01 -> 13.303 | R8: =P8 -> 1127.0247 | S8: =Q8 -> 13.303 | T8: =N8-1000 -> 127.5 | U8: =O8 -> 3231.088 | V8: =P8-1000 -> 127.02469 | W8: 3239.598
A9: G5 | B9: =B8+2.5 -> 1010 | C9: 3229.83 | D9: =D8+(SQRT((B9-B8)^2-(E9-E8)^2)) -> 1009.1851 | E9: =ABS(C9-MAX(C:C))+0.01 -> 14.561 | F9: =D9 -> 1009.1851 | G9: =E9 -> 14.561 | H9: =B9-1000 -> 10 | I9: =C9 -> 3229.83 | J9: =D9-1000 -> 9.1851154 | K9: =C66 -> 3229.83 | M9: G5 | N9: =N8+2.5 -> 1130 | O9: 3229.83 | P9: =P8+(SQRT((N9-N8)^2-(Q9-Q8)^2)) -> 1129.1851 | Q9: =ABS(O9-MAX(O:O))+0.01 -> 14.561 | R9: =P9 -> 1129.1851 | S9: =Q9 -> 14.561 | T9: =N9-1000 -> 130 | U9: =O9 -> 3229.83 | V9: =P9-1000 -> 129.18512 | W9: 3239.666
A10: G6 | B10: =B9+2.5 -> 1012.5 | C10: 3230.417 | D10: =D9+(SQRT((B10-B9)^2-(E10-E9)^2)) -> 1011.6152 | E10: =ABS(C10-MAX(C:C))+0.01 -> 13.974 | F10: =D10 -> 1011.6152 | G10: =E10 -> 13.974 | H10: =B10-1000 -> 12.5 | I10: =C10 -> 3230.417 | J10: =D10-1000 -> 11.615225 | K10: =C67 -> 3230.417 | M10: G6 | N10: =N9+2.5 -> 1132.5 | O10: 3230.417 | P10: =P9+(SQRT((N10-N9)^2-(Q10-Q9)^2)) -> 1131.6152 | Q10: =ABS(O10-MAX(O:O))+0.01 -> 13.974 | R10: =P10 -> 1131.6152 | S10: =Q10 -> 13.974 | T10: =N10-1000 -> 132.5 | U10: =O10 -> 3230.417 | V10: =P10-1000 -> 131.61522 | W10: 3239.1
A11: G7 | B11: =B10+2.5 -> 1015 | C11: 3232.585 | D11: =D10+(SQRT((B11-B10)^2-(E11-E10)^2)) -> 1012.8601 | E11: =ABS(C11-MAX(C:C))+0.01 -> 11.806 | F11: =D11 -> 1012.8601 | G11: =E11 -> 11.806 | H11: =B11-1000 -> 15 | I11: =C11 -> 3232.585 | J11: =D11-1000 -> 12.860125 | K11: =C68 -> 3232.585 | M11: G7 | N11: =N10+2.5 -> 1135 | O11: 3232.585 | P11: =P10+(SQRT((N11-N10)^2-(Q11-Q10)^2)) -> 1132.8601 | Q11: =ABS(O11-MAX(O:O))+0.01 -> 11.806 | R11: =P11 -> 1132.8601 | S11: =Q11 -> 11.806 | T11: =N11-1000 -> 135 | U11: =O11 -> 3232.585 | V11: =P11-1000 -> 132.86012 | W11: 3238.859
A12: G8 | B12: =B11+2.5 -> 1017.5 | C12: 3232.508 | D12: =D11+(SQRT((B12-B11)^2-(E12-E11)^2)) -> 1015.3589 | E12: =ABS(C12-MAX(C:C))+0.01 -> 11.883 | F12: =D12 -> 1015.3589 | G12: =E12 -> 11.883 | H12: =B12-1000 -> 17.5 | I12: =C12 -> 3232.508 | J12: =D12-1000 -> 15.358939 | K12: =C69 -> 3232.508 | M12: G8 | N12: =N11+2.5 -> 1137.5 | O12: 3232.508 | P12: =P11+(SQRT((N12-N11)^2-(Q12-Q11)^2)) -> 1135.3589 | Q12: =ABS(O12-MAX(O:O))+0.01 -> 11.883 | R12: =P12 -> 1135.3589 | S12: =Q12 -> 11.883 | T12: =N12-1000 -> 137.5 | U12: =O12 -> 3232.508 | V12: =P12-1000 -> 135.35894 | W12: 3237.75
A13: G9 | B13: =B12+2.5 -> 1020 | C13: 3233.353 | D13: =D12+(SQRT((B13-B12)^2-(E13-E12)^2)) -> 1017.7118 | E13: =ABS(C13-MAX(C:C))+0.01 -> 11.038 | F13: =D13 -> 1017.7118 | G13: =E13 -> 11.038 | H13: =B13-1000 -> 20 | I13: =C13 -> 3233.353 | J13: =D13-1000 -> 17.711804 | K13: =C70 -> 3233.353 | M13: G9 | N13: =N12+2.5 -> 1140 | O13: 3233.353 | P13: =P12+(SQRT((N13-N12)^2-(Q13-Q12)^2)) -> 1137.7118 | Q13: =ABS(O13-MAX(O:O))+0.01 -> 11.038 | R13: =P13 -> 1137.7118 | S13: =Q13 -> 11.038 | T13: =N13-1000 -> 140 | U13: =O13 -> 3233.353 | V13: =P13-1000 -> 137.7118 | W13: 3237.58
A14: G10 | B14: =B13+2.5 -> 1022.5 | C14: 3234.345 | D14: =D13+(SQRT((B14-B13)^2-(E14-E13)^2)) -> 1020.0066 | E14: =ABS(C14-MAX(C:C))+0.01 -> 10.046 | F14: =D14 -> 1020.0066 | G14: =E14 -> 10.046 | H14: =B14-1000 -> 22.5 | I14: =C14 -> 3234.345 | J14: =D14-1000 -> 20.006567 | K14: =C71 -> 3234.345 | M14: G10 | N14: =N13+2.5 -> 1142.5 | O14: 3234.345 | P14: =P13+(SQRT((N14-N13)^2-(Q14-Q13)^2)) -> 1140.0066 | Q14: =ABS(O14-MAX(O:O))+0.01 -> 10.046 | R14: =P14 -> 1140.0066 | S14: =Q14 -> 10.046 | T14: =N14-1000 -> 142.5 | U14: =O14 -> 3234.345 | V14: =P14-1000 -> 140.00657 | W14: 3237.533
A15: G11 | B15: =B14+2.5 -> 1025 | C15: 3234.74 | D15: =D14+(SQRT((B15-B14)^2-(E15-E14)^2)) -> 1022.4752 | E15: =ABS(C15-MAX(C:C))+0.01 -> 9.651 | F15: =D15 -> 1022.4752 | G15: =E15 -> 9.651 | H15: =B15-1000 -> 25 | I15: =C15 -> 3234.74 | J15: =D15-1000 -> 22.475164 | K15: =C72 -> 3234.74 | M15: G11 | N15: =N14+2.5 -> 1145 | O15: 3234.74 | P15: =P14+(SQRT((N15-N14)^2-(Q15-Q14)^2)) -> 1142.4752 | Q15: =ABS(O15-MAX(O:O))+0.01 -> 9.651 | R15: =P15 -> 1142.4752 | S15: =Q15 -> 9.651 | T15: =N15-1000 -> 145 | U15: =O15 -> 3234.74 | V15: =P15-1000 -> 142.47516 | W15: 3237.223
A16: G12 | B16: =B15+2.5 -> 1027.5 | C16: 3236.006 | D16: =D15+(SQRT((B16-B15)^2-(E16-E15)^2)) -> 1024.6309 | E16: =ABS(C16-MAX(C:C))+0.01 -> 8.385 | F16: =D16 -> 1024.6309 | G16: =E16 -> 8.385 | H16: =B16-1000 -> 27.5 | I16: =C16 -> 3236.006 | J16: =D16-1000 -> 24.630911 | K16: =C73 -> 3236.006 | M16: G12 | N16: =N15+2.5 -> 1147.5 | O16: 3236.006 | P16: =P15+(SQRT((N16-N15)^2-(Q16-Q15)^2)) -> 1144.6309 | Q16: =ABS(O16-MAX(O:O))+0.01 -> 8.385 | R16: =P16 -> 1144.6309 | S16: =Q16 -> 8.385 | T16: =N16-1000 -> 147.5 | U16: =O16 -> 3236.006 | V16: =P16-1000 -> 144.63091 | W16: 3236.129
A17: G13 | B17: =B16+2.5 -> 1030 | C17: 3236.129 | D17: =D16+(SQRT((B17-B16)^2-(E17-E16)^2)) -> 1027.1279 | E17: =ABS(C17-MAX(C:C))+0.01 -> 8.262 | F17: =D17 -> 1027.1279 | G17: =E17 -> 8.262 | H17: =B17-1000 -> 30 | I17: =C17 -> 3236.129 | J17: =D17-1000 -> 27.127883 | K17: =C74 -> 3236.129 | M17: G13 | N17: =N16+2.5 -> 1150 | O17: 3236.129 | P17: =P16+(SQRT((N17-N16)^2-(Q17-Q16)^2)) -> 1147.1279 | Q17: =ABS(O17-MAX(O:O))+0.01 -> 8.262 | R17: =P17 -> 1147.1279 | S17: =Q17 -> 8.262 | T17: =N17-1000 -> 150 | U17: =O17 -> 3236.129 | V17: =P17-1000 -> 147.12788 | W17: 3236.006
... A28: G24 | B28: =B27+2.5 -> 1057.5 | C28: 3244.381 | D28: =D27+(SQRT((B28-B27)^2-(E28-E27)^2)) -> 1052.2578 | E28: =ABS(C28-MAX(C:C))+0.01 -> 0.01 | F28: =D28 -> 1052.2578 | G28: =E28 -> 0.01 | H28: =B28-1000 -> 57.5 | I28: =C28 -> 3244.381 | J28: =D28-1000 -> 52.25779 | K28: =C85 -> 3244.381 | M28: G24 | N28: =N27+2.5 -> 1177.5 | O28: 3244.381 | P28: =P27+(SQRT((N28-N27)^2-(Q28-Q27)^2)) -> 1172.2578 | Q28: =ABS(O28-MAX(O:O))+0.01 -> 0.01 | R28: =P28 -> 1172.2578 | S28: =Q28 -> 0.01 | T28: =N28-1000 -> 177.5 | U28: =O28 -> 3244.381 | V28: =P28-1000 -> 172.25779 | W28: 3228.625
A29: OFF3 | B29: 1160 | C29: =C28-0.5 -> 3243.881 | D29: =D28+(SQRT((B29-B28)^2-(E29-E28)^2)) -> 1154.7566 | E29: =ABS(C29-MAX(C:C))+0.01 -> 0.51 | H29: 60 | I29: =C29 -> 3243.881 | J29: =H29 -> 60 | K29: =U29 -> 3243.881 | M29: OFF3 | N29: 1160 | O29: =O28-0.5 -> 3243.881 | P29: =P28+(SQRT((N29-N28)^2-(Q29-Q28)^2)) -> 1189.7506 | Q29: =ABS(O29-MAX(O:O))+0.01 -> 0.51 | T29: =T28+2.5 -> 180 | U29: =O29 -> 3243.881 | V29: =T29 -> 180 | W29: 3228.125
A30: OFF4 | B30: 1065 | C30: =C29-0.5 -> 3243.381 | H30: =B30-1000 -> 65 | I30: =C30 -> 3243.381 | J30: =H30 -> 65 | K30: =U30 -> 3243.381 | M30: OFF4 | N30: 1065 | O30: =O29-0.5 -> 3243.381 | T30: =T28+7.5 -> 185 | U30: =O30 -> 3243.381 | V30: =T30 -> 185 | W30: 3227.625
A32: Spacing | B32: 2.5 | M32: Spacing | N32: 2.5
A34: ERT
A36: Name | B36: x | C36: z | D36: RST Topo | F36: Reflex W | H36: Pygimli | J36: Pygimli ture horizontal
A38: E1 | B38: 1000 | C38: 3220.831 | D38: =B38 -> 1000 | E38: =ABS(C38-MAX(C:C))+0.01 -> 23.56 | F38: =D38 -> 1000 | G38: =E38 -> 23.56 | H38: =B38-1000 -> 0 | I38: =C38 -> 3220.831 | J38: =D38-1000 -> 0 | K38: =I38 -> 3220.831 | N38: 3244.381 | O38: 48
A39: E2 | B39: 1005 | C39: 3220.64 | D39: =D38+(SQRT((B39-B38)^2-(E39-E38)^2)) -> 1004.9964 | E39: =ABS(C39-MAX(C:C))+0.01 -> 23.751 | F39: =D39 -> 1004.9964 | G39: =E39 -> 23.751 | H39: =B39-1000 -> 5 | I39: =C39 -> 3220.64 | J39: =D39-1000 -> 4.9963506 | K39: =I39 -> 3220.64 | N39: 3220.831 | O39: 1
A40: E3 | B40: 1010 | C40: 3220.57 | D40: =D39+(SQRT((B40-B39)^2-(E40-E39)^2)) -> 1009.9959 | E40: =ABS(C40-MAX(C:C))+0.01 -> 23.821 | F40: =D40 -> 1009.9959 | G40: =E40 -> 23.821 | H40: =B40-1000 -> 10 | I40: =C40 -> 3220.57 | J40: =D40-1000 -> 9.9958605 | K40: =I40 -> 3220.57 | N40: 3220.64 | O40: 2
A41: E4 | B41: 1015 | C41: 3221.455 | D41: =D40+(SQRT((B41-B40)^2-(E41-E40)^2)) -> 1014.9169 | E41: =ABS(C41-MAX(C:C))+0.01 -> 22.936 | F41: =D41 -> 1014.9169 | G41: =E41 -> 22.936 | H41: =B41-1000 -> 15 | I41: =C41 -> 3221.455 | J41: =D41-1000 -> 14.916915 | K41: =I41 -> 3221.455 | N41: 3220.57 | O41: 3
A42: E5 | B42: 1020 | C42: 3221.27 | D42: =D41+(SQRT((B42-B41)^2-(E42-E41)^2)) -> 1019.9135 | E42: =ABS(C42-MAX(C:C))+0.01 -> 23.121 | F42: =D42 -> 1019.9135 | G42: =E42 -> 23.121 | H42: =B42-1000 -> 20 | I42: =C42 -> 3221.27 | J42: =D42-1000 -> 19.913491 | K42: =I42 -> 3221.27 | N42: 3221.455 | O42: 4
A43: E6 | B43: 1025 | C43: 3221.535 | D43: =D42+(SQRT((B43-B42)^2-(E43-E42)^2)) -> 1024.9065 | E43: =ABS(C43-MAX(C:C))+0.01 -> 22.856 | F43: =D43 -> 1024.9065 | G43: =E43 -> 22.856 | H43: =B43-1000 -> 25 | I43: =C43 -> 3221.535 | J43: =D43-1000 -> 24.906464 | K43: =I43 -> 3221.535 | N43: 3221.27 | O43: 5
A44: E7 | B44: 1030 | C44: 3222.111 | D44: =D43+(SQRT((B44-B43)^2-(E44-E43)^2)) -> 1029.8732 | E44: =ABS(C44-MAX(C:C))+0.01 -> 22.28 | F44: =D44 -> 1029.8732 | G44: =E44 -> 22.28 | H44: =B44-1000 -> 30 | I44: =C44 -> 3222.111 | J44: =D44-1000 -> 29.873175 | K44: =I44 -> 3222.111 | N44: 3221.535 | O44: 6
A45: E8 | B45: 1035 | C45: 3223.004 | D45: =D44+(SQRT((B45-B44)^2-(E45-E44)^2)) -> 1034.7928 | E45: =ABS(C45-MAX(C:C))+0.01 -> 21.387 | F45: =D45 -> 1034.7928 | G45: =E45 -> 21.387 | H45: =B45-1000 -> 35 | I45: =C45 -> 3223.004 | J45: =D45-1000 -> 34.792784 | K45: =I45 -> 3223.004 | N45: 3222.111 | O45: 7
A46: E9 | B46: 1040 | C46: 3224.328 | D46: =D45+(SQRT((B46-B45)^2-(E46-E45)^2)) -> 1039.6143 | E46: =ABS(C46-MAX(C:C))+0.01 -> 20.063 | F46: =D46 -> 1039.6143 | G46: =E46 -> 20.063 | H46: =B46-1000 -> 40 | I46: =C46 -> 3224.328 | J46: =D46-1000 -> 39.614301 | K46: =I46 -> 3224.328 | N46: 3223.004 | O46: 8
A47: E10 | B47: 1045 | C47: 3225.676 | D47: =D46+(SQRT((B47-B46)^2-(E47-E46)^2)) -> 1044.4292 | E47: =ABS(C47-MAX(C:C))+0.01 -> 18.715 | F47: =D47 -> 1044.4292 | G47: =E47 -> 18.715 | H47: =B47-1000 -> 45 | I47: =C47 -> 3225.676 | J47: =D47-1000 -> 44.429163 | K47: =I47 -> 3225.676 | N47: 3224.328 | O47: 9
A48: E11 | B48: 1050 | C48: 3225.607 | D48: =D47+(SQRT((B48-B47)^2-(E48-E47)^2)) -> 1049.4287 | E48: =ABS(C48-MAX(C:C))+0.01 -> 18.784 | F48: =D48 -> 1049.4287 | G48: =E48 -> 18.784 | H48: =B48-1000 -> 50 | I48: =C48 -> 3225.607 | J48: =D48-1000 -> 49.428687 | K48: =I48 -> 3225.607 | N48: 3225.676 | O48: 10
A49: E12 | B49: 1055 | C49: 3225.707 | D49: =D48+(SQRT((B49-B48)^2-(E49-E48)^2)) -> 1054.4277 | E49: =ABS(C49-MAX(C:C))+0.01 -> 18.684 | F49: =D49 -> 1054.4277 | G49: =E49 -> 18.684 | H49: =B49-1000 -> 55 | I49: =C49 -> 3225.707 | J49: =D49-1000 -> 54.427687 | K49: =I49 -> 3225.707 | N49: 3225.607 | O49: 11
A50: E13 | B50: 1060 | C50: 3224.435 | D50: =D49+(SQRT((B50-B49)^2-(E50-E49)^2)) -> 1059.2632 | E50: =ABS(C50-MAX(C:C))+0.01 -> 19.956 | F50: =D50 -> 1059.2632 | G50: =E50 -> 19.956 | H50: =B50-1000 -> 60 | I50: =C50 -> 3224.435 | J50: =D50-1000 -> 59.263182 | K50: =I50 -> 3224.435 | N50: 3225.707 | O50: 12
... A84: E47 | B84: 1230 | C84: 3243.012 | D84: =D83+(SQRT((B84-B83)^2-(E84-E83)^2)) -> 1225.8888 | E84: =ABS(C84-MAX(C:C))+0.01 -> 1.379 | F84: =D84 -> 1225.8888 | G84: =E84 -> 1.379 | H84: =B84-1000 -> 230 | I84: =C84 -> 3243.012 | J84: =D84-1000 -> 225.88881 | K84: =I84 -> 3243.012 | N84: 3241.326 | O84: 46
A85: E48 | B85: 1235 | C85: ='GOL01'!H2 -> 3244.381 | D85: =D84+(SQRT((B85-B84)^2-(E85-E84)^2)) -> 1230.6977 | E85: =ABS(C85-MAX(C:C))+0.01 -> 0.01 | F85: =D85 -> 1230.6977 | G85: =E85 -> 0.01 | H85: =B85-1000 -> 235 | I85: =C85 -> 3244.381 | J85: =D85-1000 -> 230.69775 | K85: =I85 -> 3244.381 | N85: 3243.012 | O85: 47

Sheet GOL05
A1: Name | B1: Easting | C1: Northing | D1: Elevation | E1: Description | F1: Longitude | G1: Latitude | H1: Ellipsoidal height | I1: Easting RMS | J1: Northing RMS | K1: Elevation RMS | L1: Lateral RMS | M1: Antenna height | N1: Antenna height units | O1: Solution status | P1: Averaging start | Q1: Averaging end | R1: Samples | S1: PDOP | T1: Base easting | U1: Base northing | V1: Base elevation | W1: Base longitude | X1: Base latitude | Y1: Base ellipsoidal height | Z1: Baseline | AA1: CS name
A2: 1 | F2: 74.486646 | G2: 42.476835 | H2: 3399.292 | I2: 0.016 | J2: 0.011 | K2: 0.01 | L2: 0.019 | M2: 2.134 | N2: m | O2: FIX | P2: 2022-08-08 10:53:13.1 UTC+06:00 | Q2: 2022-08-08 10:53:19.1 UTC+06:00 | R2: 7 | S2: 1.5 | W2: 74.487398 | X2: 42.476289 | Y2: 3414.281 | Z2: 87.544 | AA2: Global CS
A3: 2 | F3: 74.486673 | G3: 42.476796 | H3: 3398.924 | I3: 0.011 | J3: 0.016 | K3: 0.014 | L3: 0.019 | M3: 2.134 | N3: m | O3: FIX | P3: 2022-08-08 10:53:55.1 UTC+06:00 | Q3: 2022-08-08 10:54:01.1 UTC+06:00 | R3: 7 | S3: 1.3 | W3: 74.487398 | X3: 42.476289 | Y3: 3414.281 | Z3: 83.021 | AA3: Global CS
A4: 3 | F4: 74.48671 | G4: 42.47676 | H4: 3398.107 | I4: 0.014 | J4: 0.013 | K4: 0.01 | L4: 0.019 | M4: 2.134 | N4: m | O4: FIX | P4: 2022-08-08 10:54:31.1 UTC+06:00 | Q4: 2022-08-08 10:54:36.1 UTC+06:00 | R4: 6 | S4: 1.3 | W4: 74.487398 | X4: 42.476289 | Y4: 3414.281 | Z4: 78.371 | AA4: Global CS
A5: 4 | F5: 74.486743 | G5: 42.476723 | H5: 3396.931 | I5: 0.019 | J5: 0.011 | K5: 0.01 | L5: 0.022 | M5: 2.134 | N5: m | O5: FIX | P5: 2022-08-08 10:55:07.1 UTC+06:00 | Q5: 2022-08-08 10:55:13.1 UTC+06:00 | R5: 7 | S5: 1.3 | W5: 74.487398 | X5: 42.476289 | Y5: 3414.281 | Z5: 73.833 | AA5: Global CS
A6: 5 | F6: 74.486777 | G6: 42.476687 | H6: 3396.416 | I6: 0.011 | J6: 0.012 | K6: 0.011 | L6: 0.016 | M6: 2.134 | N6: m | O6: FIX | P6: 2022-08-08 10:55:53.1 UTC+06:00 | Q6: 2022-08-08 10:55:59.1 UTC+06:00 | R6: 7 | S6: 1.3 | W6: 74.487398 | X6: 42.476289 | Y6: 3414.281 | Z6: 69.344 | AA6: Global CS
A7: 6 | F7: 74.486809 | G7: 42.476652 | H7: 3396.554 | I7: 0.01 | J7: 0.013 | K7: 0.012 | L7: 0.017 | M7: 2.134 | N7: m | O7: FIX | P7: 2022-08-08 10:56:40.1 UTC+06:00 | Q7: 2022-08-08 10:56:46.1 UTC+06:00 | R7: 7 | S7: 1.3 | W7: 74.487398 | X7: 42.476289 | Y7: 3414.281 | Z7: 64.88 | AA7: Global CS
A8: 7 | F8: 74.486848 | G8: 42.476618 | H8: 3397.082 | I8: 0.015 | J8: 0.013 | K8: 0.01 | L8: 0.02 | M8: 2.134 | N8: m | O8: FIX | P8: 2022-08-08 10:57:25.1 UTC+06:00 | Q8: 2022-08-08 10:57:30.1 UTC+06:00 | R8: 6 | S8: 1.3 | W8: 74.487398 | X8: 42.476289 | Y8: 3414.281 | Z8: 60.023 | AA8: Global CS
A9: 8 | F9: 74.486877 | G9: 42.476574 | H9: 3397.918 | I9: 0.01 | J9: 0.019 | K9: 0.014 | L9: 0.022 | M9: 2.134 | N9: m | O9: FIX | P9: 2022-08-08 10:58:28.1 UTC+06:00 | Q9: 2022-08-08 10:58:34.1 UTC+06:00 | R9: 7 | S9: 1.3 | W9: 74.487398 | X9: 42.476289 | Y9: 3414.281 | Z9: 55.112 | AA9: Global CS
A10: 9 | F10: 74.48691 | G10: 42.476539 | H10: 3398.55 | I10: 0.013 | J10: 0.015 | K10: 0.01 | L10: 0.02 | M10: 2.134 | N10: m | O10: FIX | P10: 2022-08-08 10:59:25.1 UTC+06:00 | Q10: 2022-08-08 10:59:30.1 UTC+06:00 | R10: 6 | S10: 1.3 | W10: 74.487398 | X10: 42.476289 | Y10: 3414.281 | Z10: 50.593 | AA10: Global CS
A11: 10 | F11: 74.486944 | G11: 42.476502 | H11: 3399.138 | I11: 0.011 | J11: 0.012 | K11: 0.011 | L11: 0.016 | M11: 2.134 | N11: m | O11: FIX | P11: 2022-08-08 11:00:13.1 UTC+06:00 | Q11: 2022-08-08 11:00:18.1 UTC+06:00 | R11: 6 | S11: 1.3 | W11: 74.487398 | X11: 42.476289 | Y11: 3414.281 | Z11: 46.074 | AA11: Global CS
A12: 11 | F12: 74.486976 | G12: 42.476469 | H12: 3399.95 | I12: 0.013 | J12: 0.012 | K12: 0.012 | L12: 0.017 | M12: 2.134 | N12: m | O12: FIX | P12: 2022-08-08 11:01:01.1 UTC+06:00 | Q12: 2022-08-08 11:01:06.1 UTC+06:00 | R12: 6 | S12: 1.3 | W12: 74.487398 | X12: 42.476289 | Y12: 3414.281 | Z12: 41.805 | AA12: Global CS
A13: 12 | F13: 74.487008 | G13: 42.476426 | H13: 3400.837 | I13: 0.013 | J13: 0.011 | K13: 0.011 | L13: 0.016 | M13: 2.134 | N13: m | O13: FIX | P13: 2022-08-08 11:01:43.1 UTC+06:00 | Q13: 2022-08-08 11:01:48.2 UTC+06:00 | R13: 6 | S13: 1.3 | W13: 74.487398 | X13: 42.476289 | Y13: 3414.281 | Z13: 37.188 | AA13: Global CS
... A49: 48 | F49: 74.488144 | G49: 42.475073 | H49: 3420.621 | I49: 0.011 | J49: 0.011 | K49: 0.011 | L49: 0.015 | M49: 2.134 | N49: m | O49: FIX | P49: 2022-08-08 11:21:22.2 UTC+06:00 | Q49: 2022-08-08 11:21:28.2 UTC+06:00 | R49: 7 | S49: 1.4 | W49: 74.487398 | X49: 42.476289 | Y49: 3414.281 | Z49: 148.772 | AA49: Global CS

Sheet GOL06
A1: Name | B1: Easting | C1: Northing | D1: Elevation | E1: Description | F1: Longitude | G1: Latitude | H1: Ellipsoidal height | I1: Easting RMS | J1: Northing RMS | K1: Elevation RMS | L1: Lateral RMS | M1: Antenna height | N1: Antenna height units | O1: Solution status | P1: Averaging start | Q1: Averaging end | R1: Samples | S1: PDOP | T1: Base easting | U1: Base northing | V1: Base elevation | W1: Base longitude | X1: Base latitude | Y1: Base ellipsoidal height | Z1: Baseline | AA1: CS name
A2: 1 | F2: 74.489797 | G2: 42.479998 | H2: 3212.296 | I2: 0.016 | J2: 0.077 | K2: 0.025 | L2: 0.079 | M2: 2.134 | N2: m | O2: FIX | P2: 2022-08-08 16:32:08.5 UTC+06:00 | Q2: 2022-08-08 16:32:13.5 UTC+06:00 | R2: 6 | S2: 1.6 | W2: 74.489796 | X2: 42.480001 | Y2: 3213.017 | Z2: 1.461 | AA2: Global CS
A3: 1 | F3: 74.489815 | G3: 42.480017 | H3: 3211.804 | I3: 0.011 | J3: 0.013 | K3: 0.015 | L3: 0.017 | M3: 2.134 | N3: m | O3: FIX | P3: 2022-08-08 16:33:35.5 UTC+06:00 | Q3: 2022-08-08 16:33:41.5 UTC+06:00 | R3: 7 | S3: 1.5 | W3: 74.489796 | X3: 42.480001 | Y3: 3213.017 | Z3: 2.528 | AA3: Global CS
A4: 2 | F4: 74.489852 | G4: 42.480054 | H4: 3210.055 | I4: 0.012 | J4: 0.01 | K4: 0.011 | L4: 0.016 | M4: 2.134 | N4: m | O4: FIX | P4: 2022-08-08 16:34:06.5 UTC+06:00 | Q4: 2022-08-08 16:34:11.6 UTC+06:00 | R4: 6 | S4: 1.4 | W4: 74.489796 | X4: 42.480001 | Y4: 3213.017 | Z4: 7.515 | AA4: Global CS
A5: 3 | F5: 74.489882 | G5: 42.480088 | H5: 3208.605 | I5: 0.013 | J5: 0.023 | K5: 0.014 | L5: 0.026 | M5: 2.134 | N5: m | O5: FIX | P5: 2022-08-08 16:34:56.5 UTC+06:00 | Q5: 2022-08-08 16:35:02.5 UTC+06:00 | R5: 7 | S5: 1.4 | W5: 74.489796 | X5: 42.480001 | Y5: 3213.017 | Z5: 12.223 | AA5: Global CS
A6: 4 | F6: 74.489919 | G6: 42.480123 | H6: 3207.222 | I6: 0.326 | J6: 0.115 | K6: 0.065 | L6: 0.346 | M6: 2.134 | N6: m | O6: FIX | P6: 2022-08-08 16:36:51.6 UTC+06:00 | Q6: 2022-08-08 16:36:57.6 UTC+06:00 | R6: 7 | S6: 1.4 | W6: 74.489796 | X6: 42.480001 | Y6: 3213.017 | Z6: 17.829 | AA6: Global CS
A7: 5 | F7: 74.489946 | G7: 42.480163 | H7: 3205.554 | I7: 0.011 | J7: 0.013 | K7: 0.011 | L7: 0.017 | M7: 2.134 | N7: m | O7: FIX | P7: 2022-08-08 16:37:36.6 UTC+06:00 | Q7: 2022-08-08 16:37:42.6 UTC+06:00 | R7: 7 | S7: 1.4 | W7: 74.489796 | X7: 42.480001 | Y7: 3213.017 | Z7: 22.482 | AA7: Global CS
A8: 6 | F8: 74.48997 | G8: 42.480201 | H8: 3204.301 | I8: 0.011 | J8: 0.048 | K8: 0.01 | L8: 0.049 | M8: 2.134 | N8: m | O8: FIX | P8: 2022-08-08 16:38:18.6 UTC+06:00 | Q8: 2022-08-08 16:38:23.6 UTC+06:00 | R8: 6 | S8: 1.4 | W8: 74.489796 | X8: 42.480001 | Y8: 3213.017 | Z8: 27.202 | AA8: Global CS
A9: 7 | F9: 74.489993 | G9: 42.480236 | H9: 3202.629 | I9: 0.016 | J9: 0.015 | K9: 0.011 | L9: 0.021 | M9: 2.134 | N9: m | O9: FIX | P9: 2022-08-08 16:38:49.6 UTC+06:00 | Q9: 2022-08-08 16:38:55.6 UTC+06:00 | R9: 7 | S9: 1.5 | W9: 74.489796 | X9: 42.480001 | Y9: 3213.017 | Z9: 31.864 | AA9: Global CS
A10: 8 | F10: 74.490027 | G10: 42.480285 | H10: 3201.624 | I10: 0.015 | J10: 0.019 | K10: 0.011 | L10: 0.024 | M10: 2.134 | N10: m | O10: FIX | P10: 2022-08-08 16:39:34.6 UTC+06:00 | Q10: 2022-08-08 16:39:39.6 UTC+06:00 | R10: 6 | S10: 1.3 | W10: 74.489796 | X10: 42.480001 | Y10: 3213.017 | Z10: 37.969 | AA10: Global CS
A11: 9 | F11: 74.490042 | G11: 42.480317 | H11: 3200.39 | I11: 0.019 | J11: 0.015 | K11: 0.01 | L11: 0.025 | M11: 2.134 | N11: m | O11: FIX | P11: 2022-08-08 16:40:08.6 UTC+06:00 | Q11: 2022-08-08 16:40:13.6 UTC+06:00 | R11: 6 | S11: 1.5 | W11: 74.489796 | X11: 42.480001 | Y11: 3213.017 | Z11: 41.89 | AA11: Global CS
A12: 10 | F12: 74.490077 | G12: 42.480349 | H12: 3199.252 | I12: 0.015 | J12: 0.011 | K12: 0.011 | L12: 0.019 | M12: 2.134 | N12: m | O12: FIX | P12: 2022-08-08 16:40:44.6 UTC+06:00 | Q12: 2022-08-08 16:40:50.6 UTC+06:00 | R12: 7 | S12: 1.5 | W12: 74.489796 | X12: 42.480001 | Y12: 3213.017 | Z12: 46.496 | AA12: Global CS
A13: 11 | F13: 74.490096 | G13: 42.480396 | H13: 3199.04 | I13: 0.011 | J13: 0.019 | K13: 0.011 | L13: 0.022 | M13: 2.134 | N13: m | O13: FIX | P13: 2022-08-08 16:41:26.6 UTC+06:00 | Q13: 2022-08-08 16:41:32.6 UTC+06:00 | R13: 7 | S13: 1.5 | W13: 74.489796 | X13: 42.480001 | Y13: 3213.017 | Z13: 51.735 | AA13: Global CS
... A46: 44 | F46: 74.490957 | G46: 42.481562 | H46: 3182.962 | I46: 0.01 | J46: 0.01 | K46: 0.014 | L46: 0.015 | M46: 1.934 | N46: m | O46: FIX | P46: 2022-08-08 17:36:02.9 UTC+06:00 | Q46: 2022-08-08 17:36:08.0 UTC+06:00 | R46: 6 | S46: 1.7 | W46: 74.489796 | X46: 42.480001 | Y46: 3213.017 | Z46: 200.006 | AA46: Global CS
A47: 45 | F47: 74.490991 | G47: 42.481619 | H47: 3177.252 | I47: 0.821 | J47: 0.386 | K47: 0.752 | L47: 0.907 | M47: 1.934 | N47: m | O47: SINGLE | P47: 2022-08-08 17:36:56.0 UTC+06:00 | Q47: 2022-08-08 17:37:01.9 UTC+06:00 | R47: 7 | S47: 1.5 | AA47: Global CS
A48: 46 | F48: 74.491011 | G48: 42.481664 | H48: 3174.121 | I48: 0.586 | J48: 0.3 | K48: 0.637 | L48: 0.658 | M48: 1.934 | N48: m | O48: SINGLE | P48: 2022-08-08 17:37:31.9 UTC+06:00 | Q48: 2022-08-08 17:37:38.0 UTC+06:00 | R48: 7 | S48: 1.4 | AA48: Global CS
A49: 47 | F49: 74.491034 | G49: 42.481681 | H49: 3173.359 | I49: 0.55 | J49: 0.3 | K49: 0.656 | L49: 0.627 | M49: 1.934 | N49: m | O49: SINGLE | P49: 2022-08-08 17:38:17.0 UTC+06:00 | Q49: 2022-08-08 17:38:22.9 UTC+06:00 | R49: 7 | S49: 1.5 | AA49: Global CS
A50: 48 | F50: 74.491085 | G50: 42.481717 | H50: 3172.348 | I50: 0.551 | J50: 0.304 | K50: 0.67 | L50: 0.629 | M50: 1.934 | N50: m | O50: SINGLE | P50: 2022-08-08 17:38:57.0 UTC+06:00 | Q50: 2022-08-08 17:39:02.0 UTC+06:00 | R50: 6 | S50: 1.5 | AA50: Global CS
A51: 49 | F51: 74.491126 | G51: 42.481755 | H51: 3171.611 | I51: 0.569 | J51: 0.301 | K51: 0.688 | L51: 0.643 | M51: 1.934 | N51: m | O51: SINGLE | P51: 2022-08-08 17:39:28.0 UTC+06:00 | Q51: 2022-08-08 17:39:34.0 UTC+06:00 | R51: 7 | S51: 1.5 | AA51: Global CS
A52: 50 | F52: 74.49113 | G52: 42.481792 | H52: 3170.552 | I52: 0.564 | J52: 0.301 | K52: 0.677 | L52: 0.639 | M52: 1.934 | N52: m | O52: SINGLE | P52: 2022-08-08 17:40:14.0 UTC+06:00 | Q52: 2022-08-08 17:40:19.0 UTC+06:00 | R52: 6 | S52: 1.5 | AA52: Global CS

Sheet GOL07
A1: Name | B1: Easting | C1: Northing | D1: Elevation | E1: Description | F1: Longitude | G1: Latitude | H1: Ellipsoidal height | I1: Easting RMS | J1: Northing RMS | K1: Elevation RMS | L1: Lateral RMS | M1: Antenna height | N1: Antenna height units | O1: Solution status | P1: Averaging start | Q1: Averaging end | R1: Samples | S1: PDOP | T1: Base easting | U1: Base northing | V1: Base elevation | W1: Base longitude | X1: Base latitude | Y1: Base ellipsoidal height | Z1: Baseline | AA1: CS name
A2: 1 | F2: 74.499173 | G2: 42.482186 | H2: 3192.405 | I2: 0.53 | J2: 0.407 | K2: 1 | L2: 0.668 | M2: 2.134 | N2: m | O2: SINGLE | P2: 2022-08-09 15:16:52.7 UTC+06:00 | Q2: 2022-08-09 15:16:57.7 UTC+06:00 | R2: 6 | S2: 1.3 | AA2: Global CS
A3: 2 | F3: 74.499134 | G3: 42.482207 | H3: 3191.74 | I3: 0.53 | J3: 0.423 | K3: 1 | L3: 0.678 | M3: 2.134 | N3: m | O3: SINGLE | P3: 2022-08-09 15:17:30.7 UTC+06:00 | Q3: 2022-08-09 15:17:36.7 UTC+06:00 | R3: 7 | S3: 1.3 | AA3: Global CS
A4: 3 | F4: 74.499092 | G4: 42.482239 | H4: 3191.546 | I4: 0.525 | J4: 0.428 | K4: 1 | L4: 0.677 | M4: 2.134 | N4: m | O4: SINGLE | P4: 2022-08-09 15:17:50.7 UTC+06:00 | Q4: 2022-08-09 15:17:55.7 UTC+06:00 | R4: 6 | S4: 1.4 | AA4: Global CS
A5: 4 | F5: 74.499041 | G5: 42.482266 | H5: 3191.55 | I5: 0.47 | J5: 0.412 | K5: 0.986 | L5: 0.626 | M5: 2.134 | N5: m | O5: SINGLE | P5: 2022-08-09 15:18:09.7 UTC+06:00 | Q5: 2022-08-09 15:18:14.7 UTC+06:00 | R5: 6 | S5: 1.4 | AA5: Global CS
A6: 5 | F6: 74.498981 | G6: 42.482302 | H6: 3189.879 | I6: 0.37 | J6: 0.365 | K6: 0.835 | L6: 0.519 | M6: 2.134 | N6: m | O6: SINGLE | P6: 2022-08-09 15:18:47.7 UTC+06:00 | Q6: 2022-08-09 15:18:53.7 UTC+06:00 | R6: 7 | S6: 1.4 | AA6: Global CS
A7: 6 | F7: 74.498938 | G7: 42.482321 | H7: 3190.536 | I7: 0.373 | J7: 0.351 | K7: 0.803 | L7: 0.512 | M7: 2.134 | N7: m | O7: SINGLE | P7: 2022-08-09 15:19:06.7 UTC+06:00 | Q7: 2022-08-09 15:19:12.7 UTC+06:00 | R7: 7 | S7: 1.2 | AA7: Global CS
A8: 7 | F8: 74.498891 | G8: 42.482352 | H8: 3190.148 | I8: 0.46 | J8: 0.407 | K8: 0.921 | L8: 0.614 | M8: 2.134 | N8: m | O8: SINGLE | P8: 2022-08-09 15:19:24.7 UTC+06:00 | Q8: 2022-08-09 15:19:29.7 UTC+06:00 | R8: 6 | S8: 1.3 | AA8: Global CS
A9: 8 | F9: 74.498836 | G9: 42.482387 | H9: 3188.367 | I9: 0.502 | J9: 0.413 | K9: 0.99 | L9: 0.65 | M9: 2.134 | N9: m | O9: SINGLE | P9: 2022-08-09 15:20:00.7 UTC+06:00 | Q9: 2022-08-09 15:20:05.7 UTC+06:00 | R9: 6 | S9: 1.2 | AA9: Global CS
A10: 9 | F10: 74.498798 | G10: 42.482414 | H10: 3188.108 | I10: 0.501 | J10: 0.419 | K10: 0.996 | L10: 0.653 | M10: 2.134 | N10: m | O10: SINGLE | P10: 2022-08-09 15:20:16.7 UTC+06:00 | Q10: 2022-08-09 15:20:21.7 UTC+06:00 | R10: 6 | S10: 1.2 | AA10: Global CS
A11: 10 | F11: 74.498756 | G11: 42.482447 | H11: 3187.65 | I11: 0.472 | J11: 0.393 | K11: 0.939 | L11: 0.614 | M11: 2.134 | N11: m | O11: SINGLE | P11: 2022-08-09 15:20:37.7 UTC+06:00 | Q11: 2022-08-09 15:20:48.7 UTC+06:00 | R11: 12 | S11: 1.2 | AA11: Global CS
A12: 11 | F12: 74.498718 | G12: 42.482477 | H12: 3187.233 | I12: 0.416 | J12: 0.292 | K12: 0.772 | L12: 0.509 | M12: 2.134 | N12: m | O12: SINGLE | P12: 2022-08-09 15:21:06.7 UTC+06:00 | Q12: 2022-08-09 15:21:17.7 UTC+06:00 | R12: 12 | S12: 1.1 | AA12: Global CS
A13: 12 | F13: 74.498664 | G13: 42.4825 | H13: 3187.506 | I13: 0.413 | J13: 0.301 | K13: 0.772 | L13: 0.511 | M13: 2.134 | N13: m | O13: SINGLE | P13: 2022-08-09 15:21:32.7 UTC+06:00 | Q13: 2022-08-09 15:21:42.7 UTC+06:00 | R13: 11 | S13: 1.1 | AA13: Global CS
... A121: 120 | F121: 74.493649 | G121: 42.485361 | H121: 3107.404 | I121: 0.352 | J121: 0.23 | K121: 0.728 | L121: 0.421 | M121: 2.134 | N121: m | O121: SINGLE | P121: 2022-08-10 14:49:15.9 UTC+06:00 | Q121: 2022-08-10 14:49:25.9 UTC+06:00 | R121: 11 | S121: 1.3 | AA121: Global CS

Sheet GOL07_RST_c
A1: Name | B1: x | C1: z | D1: RST Topo | F1: Reflex W | H1: Pygimli | J1: Pygimli true
A3: OFF1 | B3: 992.5 | C3: =C4 -> 3143.336 | D3: =B3 -> 992.5 | E3: =ABS(C3-MAX(C:C))+0.01 -> 0.01 | H3: =B3-1000 -> -7.5 | I3: =C3 -> 3143.336 | J3: =H3 -> -7.5 | K3: =I3 -> 3143.336
A4: G1 | B4: 1000 | C4: 3143.336 | D4: =B4 -> 1000 | E4: =ABS(C4-MAX(C:C))+0.01 -> 0.01 | F4: =D4 -> 1000 | G4: =E4 -> 0.01 | H4: =B4-1000 -> 0 | I4: =C4 -> 3143.336 | J4: =D4-1000 -> 0 | K4: =I4 -> 3143.336
A5: G2 | B5: =B4+5 -> 1005 | C5: 3141.693 | D5: =D4+(SQRT((B5-B4)^2-(E5-E4)^2)) -> 1004.7223 | E5: =ABS(C5-MAX(C:C))+0.01 -> 1.653 | F5: =D5 -> 1004.7223 | G5: =E5 -> 1.653 | H5: =B5-1000 -> 5 | I5: =C5 -> 3141.693 | J5: =D5-1000 -> 4.7223459 | K5: =I5 -> 3141.693
A6: G3 | B6: =B5+5 -> 1010 | C6: 3140.477 | D6: =D5+(SQRT((B6-B5)^2-(E6-E5)^2)) -> 1009.5722 | E6: =ABS(C6-MAX(C:C))+0.01 -> 2.869 | F6: =D6 -> 1009.5722 | G6: =E6 -> 2.869 | H6: =B6-1000 -> 10 | I6: =C6 -> 3140.477 | J6: =D6-1000 -> 9.5722267 | K6: =I6 -> 3140.477
A7: G4 | B7: =B6+5 -> 1015 | C7: 3139.216 | D7: =D6+(SQRT((B7-B6)^2-(E7-E6)^2)) -> 1014.4106 | E7: =ABS(C7-MAX(C:C))+0.01 -> 4.13 | F7: =D7 -> 1014.4106 | G7: =E7 -> 4.13 | H7: =B7-1000 -> 15 | I7: =C7 -> 3139.216 | J7: =D7-1000 -> 14.410602 | K7: =I7 -> 3139.216
A8: G5 | B8: =B7+5 -> 1020 | C8: 3141.359 | D8: =D7+(SQRT((B8-B7)^2-(E8-E7)^2)) -> 1018.9281 | E8: =ABS(C8-MAX(C:C))+0.01 -> 1.987 | F8: =D8 -> 1018.9281 | G8: =E8 -> 1.987 | H8: =B8-1000 -> 20 | I8: =C8 -> 3141.359 | J8: =D8-1000 -> 18.928074 | K8: =I8 -> 3141.359
A9: G6 | B9: =B8+5 -> 1025 | C9: 3142.444 | D9: =D8+(SQRT((B9-B8)^2-(E9-E8)^2)) -> 1023.8089 | E9: =ABS(C9-MAX(C:C))+0.01 -> 0.902 | F9: =D9 -> 1023.8089 | G9: =E9 -> 0.902 | H9: =B9-1000 -> 25 | I9: =C9 -> 3142.444 | J9: =D9-1000 -> 23.808932 | K9: =I9 -> 3142.444
A10: G7 | B10: =B9+5 -> 1030 | C10: 3142.881 | D10: =D9+(SQRT((B10-B9)^2-(E10-E9)^2)) -> 1028.7898 | E10: =ABS(C10-MAX(C:C))+0.01 -> 0.465 | F10: =D10 -> 1028.7898 | G10: =E10 -> 0.465 | H10: =B10-1000 -> 30 | I10: =C10 -> 3142.881 | J10: =D10-1000 -> 28.789799 | K10: =I10 -> 3142.881
A11: G8 | B11: =B10+5 -> 1035 | C11: 3141.314 | D11: =D10+(SQRT((B11-B10)^2-(E11-E10)^2)) -> 1033.5379 | E11: =ABS(C11-MAX(C:C))+0.01 -> 2.032 | F11: =D11 -> 1033.5379 | G11: =E11 -> 2.032 | H11: =B11-1000 -> 35 | I11: =C11 -> 3141.314 | J11: =D11-1000 -> 33.537905 | K11: =I11 -> 3141.314
A12: G9 | B12: =B11+5 -> 1040 | C12: 3140.285 | D12: =D11+(SQRT((B12-B11)^2-(E12-E11)^2)) -> 1038.4309 | E12: =ABS(C12-MAX(C:C))+0.01 -> 3.061 | F12: =D12 -> 1038.4309 | G12: =E12 -> 3.061 | H12: =B12-1000 -> 40 | I12: =C12 -> 3140.285 | J12: =D12-1000 -> 38.430875 | K12: =I12 -> 3140.285
A13: G10 | B13: =B12+5 -> 1045 | C13: 3141.239 | D13: =D12+(SQRT((B13-B12)^2-(E13-E12)^2)) -> 1043.339 | E13: =ABS(C13-MAX(C:C))+0.01 -> 2.107 | F13: =D13 -> 1043.339 | G13: =E13 -> 2.107 | H13: =B13-1000 -> 45 | I13: =C13 -> 3141.239 | J13: =D13-1000 -> 43.33902 | K13: =I13 -> 3141.239
A14: G11 | B14: =B13+5 -> 1050 | C14: 3141.273 | D14: =D13+(SQRT((B14-B13)^2-(E14-E13)^2)) -> 1048.3389 | E14: =ABS(C14-MAX(C:C))+0.01 -> 2.073 | F14: =D14 -> 1048.3389 | G14: =E14 -> 2.073 | H14: =B14-1000 -> 50 | I14: =C14 -> 3141.273 | J14: =D14-1000 -> 48.338904 | K14: =I14 -> 3141.273
A15: G12 | B15: =B14+5 -> 1055 | C15: 3139.506 | D15: =D14+(SQRT((B15-B14)^2-(E15-E14)^2)) -> 1053.0163 | E15: =ABS(C15-MAX(C:C))+0.01 -> 3.84 | F15: =D15 -> 1053.0163 | G15: =E15 -> 3.84 | H15: =B15-1000 -> 55 | I15: =C15 -> 3139.506 | J15: =D15-1000 -> 53.016266 | K15: =I15 -> 3139.506
A16: G13 | B16: =B15+5 -> 1060 | C16: 3137.565 | D16: =D15+(SQRT((B16-B15)^2-(E16-E15)^2)) -> 1057.6241 | E16: =ABS(C16-MAX(C:C))+0.01 -> 5.781 | F16: =D16 -> 1057.6241 | G16: =E16 -> 5.781 | H16: =B16-1000 -> 60 | I16: =C16 -> 3137.565 | J16: =D16-1000 -> 57.624141 | K16: =I16 -> 3137.565
... A27: G24 | B27: =B26+5 -> 1115 | C27: 3129.859 | D27: =D26+(SQRT((B27-B26)^2-(E27-E26)^2)) -> 1111.493 | E27: =ABS(C27-MAX(C:C))+0.01 -> 13.487 | F27: =D27 -> 1111.493 | G27: =E27 -> 13.487 | H27: =B27-1000 -> 115 | I27: =C27 -> 3129.859 | J27: =D27-1000 -> 111.493 | K27: =I27 -> 3129.859
A28: OFF3 | B28: 1122.5 | C28: 3127.896 | D28: =D27+(SQRT((B28-B27)^2-(E28-E27)^2)) -> 1118.7316 | E28: =ABS(C28-MAX(C:C))+0.01 -> 15.45 | H28: 122.5 | I28: =I27-0.5 -> 3129.359 | J28: =D28-1000 -> 118.73155 | K28: =I28 -> 3129.359
A30: Spacing | B30: 5

Sheet GOL08
A1: Name | B1: Easting | C1: Northing | D1: Elevation | E1: Description | F1: Longitude | G1: Latitude | H1: Ellipsoidal height | I1: Easting RMS | J1: Northing RMS | K1: Elevation RMS | L1: Lateral RMS | M1: Antenna height | N1: Antenna height units | O1: Solution status | P1: Averaging start | Q1: Averaging end | R1: Samples | S1: PDOP | T1: Base easting | U1: Base northing | V1: Base elevation | W1: Base longitude | X1: Base latitude | Y1: Base ellipsoidal height | Z1: Baseline | AA1: CS name
A2: 1 | F2: 74.489908 | G2: 42.488778 | H2: 3021.208 | I2: 0.563 | J2: 0.429 | K2: 1.302 | L2: 0.708 | M2: 2.134 | N2: m | O2: SINGLE | P2: 2022-08-11 10:37:12.9 UTC+06:00 | Q2: 2022-08-11 10:37:22.9 UTC+06:00 | R2: 11 | S2: 1.5 | AA2: Global CS
A3: 2 | F3: 74.489963 | G3: 42.488774 | H3: 3022.489 | I3: 0.582 | J3: 0.431 | K3: 1.304 | L3: 0.724 | M3: 2.134 | N3: m | O3: SINGLE | P3: 2022-08-11 10:37:44.9 UTC+06:00 | Q3: 2022-08-11 10:37:51.9 UTC+06:00 | R3: 8 | S3: 1.5 | AA3: Global CS
A4: 3 | F4: 74.490025 | G4: 42.488761 | H4: 3025.109 | I4: 0.514 | J4: 0.381 | K4: 1.162 | L4: 0.64 | M4: 2.134 | N4: m | O4: SINGLE | P4: 2022-08-11 10:38:03.9 UTC+06:00 | Q4: 2022-08-11 10:38:12.0 UTC+06:00 | R4: 9 | S4: 1.5 | AA4: Global CS
A5: 4 | F5: 74.490084 | G5: 42.488757 | H5: 3027.86 | I5: 0.431 | J5: 0.318 | K5: 0.904 | L5: 0.535 | M5: 2.134 | N5: m | O5: SINGLE | P5: 2022-08-11 10:38:30.9 UTC+06:00 | Q5: 2022-08-11 10:38:37.9 UTC+06:00 | R5: 8 | S5: 1.5 | AA5: Global CS
A6: 5 | F6: 74.490141 | G6: 42.488746 | H6: 3029.766 | I6: 0.365 | J6: 0.289 | K6: 0.771 | L6: 0.466 | M6: 2.134 | N6: m | O6: SINGLE | P6: 2022-08-11 10:38:57.9 UTC+06:00 | Q6: 2022-08-11 10:39:05.9 UTC+06:00 | R6: 9 | S6: 1.5 | AA6: Global CS
A7: 6 | F7: 74.490198 | G7: 42.488743 | H7: 3031.085 | I7: 0.395 | J7: 0.26 | K7: 0.754 | L7: 0.473 | M7: 2.134 | N7: m | O7: SINGLE | P7: 2022-08-11 10:39:19.9 UTC+06:00 | Q7: 2022-08-11 10:39:26.9 UTC+06:00 | R7: 8 | S7: 1.7 | AA7: Global CS
A8: 7 | F8: 74.490254 | G8: 42.488731 | H8: 3032.597 | I8: 0.369 | J8: 0.266 | K8: 0.77 | L8: 0.455 | M8: 2.134 | N8: m | O8: SINGLE | P8: 2022-08-11 10:39:44.9 UTC+06:00 | Q8: 2022-08-11 10:39:52.9 UTC+06:00 | R8: 9 | S8: 1.7 | AA8: Global CS
A9: 8 | F9: 74.4903 | G9: 42.488723 | H9: 3033.784 | I9: 0.374 | J9: 0.266 | K9: 0.746 | L9: 0.459 | M9: 2.134 | N9: m | O9: SINGLE | P9: 2022-08-11 10:40:06.0 UTC+06:00 | Q9: 2022-08-11 10:40:13.9 UTC+06:00 | R9: 9 | S9: 1.7 | AA9: Global CS
A10: 9 | F10: 74.49036 | G10: 42.488719 | H10: 3034.738 | I10: 0.39 | J10: 0.311 | K10: 0.856 | L10: 0.499 | M10: 2.134 | N10: m | O10: SINGLE | P10: 2022-08-11 10:40:36.9 UTC+06:00 | Q10: 2022-08-11 10:40:43.9 UTC+06:00 | R10: 8 | S10: 1.7 | AA10: Global CS
A11: 10 | F11: 74.490411 | G11: 42.488706 | H11: 3035.947 | I11: 0.526 | J11: 0.406 | K11: 1.202 | L11: 0.664 | M11: 2.134 | N11: m | O11: SINGLE | P11: 2022-08-11 10:41:12.0 UTC+06:00 | Q11: 2022-08-11 10:41:20.0 UTC+06:00 | R11: 9 | S11: 1.7 | AA11: Global CS
A12: 11 | F12: 74.490463 | G12: 42.488693 | H12: 3036.497 | I12: 0.561 | J12: 0.433 | K12: 1.301 | L12: 0.709 | M12: 2.134 | N12: m | O12: SINGLE | P12: 2022-08-11 10:41:40.0 UTC+06:00 | Q12: 2022-08-11 10:41:47.0 UTC+06:00 | R12: 8 | S12: 1.7 | AA12: Global CS
A13: 12 | F13: 74.490521 | G13: 42.488684 | H13: 3037.162 | I13: 0.578 | J13: 0.44 | K13: 1.302 | L13: 0.727 | M13: 2.134 | N13: m | O13: SINGLE | P13: 2022-08-11 10:42:01.0 UTC+06:00 | Q13: 2022-08-11 10:42:09.0 UTC+06:00 | R13: 9 | S13: 1.7 | AA13: Global CS
... A49: 48 | F49: 74.492479 | G49: 42.488839 | H49: 3088.331 | I49: 0.902 | J49: 0.971 | K49: 2.253 | L49: 1.325 | M49: 2.134 | N49: m | O49: SINGLE | P49: 2022-08-11 11:00:31.0 UTC+06:00 | Q49: 2022-08-11 11:00:53.0 UTC+06:00 | R49: 23 | S49: 2.1 | AA49: Global CS

Sheet Topo
A1: GOL01 | D1: GOL05 | G1: GOL06 | J1: GOL07 | M1: GOL08
A2: x | B2: z | D2: x | E2: z | G2: x | H2: z | J2: x | K2: z | M2: x | N2: z
A3: 0 | B3: 3220.831 | D3: 0 | E3: 3399.292 | G3: 0 | H3: 3211.804 | J3: 0 | K3: 3192.405 | M3: 0 | N3: 3021.208
A4: 5 | B4: 3220.64 | D4: 5 | E4: 3398.924 | G4: 5 | H4: 3210.055 | J4: 5 | K4: 3191.74 | M4: 5 | N4: 3022.489
A5: 10 | B5: 3220.57 | D5: 10 | E5: 3398.107 | G5: 10 | H5: 3208.605 | J5: 10 | K5: 3191.546 | M5: 10 | N5: 3025.109
A6: 15 | B6: 3221.455 | D6: 15 | E6: 3396.931 | G6: 15 | H6: 3207.222 | J6: 15 | K6: 3191.55 | M6: 15 | N6: 3027.86
A7: 20 | B7: 3221.27 | D7: 20 | E7: 3396.416 | G7: 20 | H7: 3205.554 | J7: 20 | K7: 3189.879 | M7: 20 | N7: 3029.766
A8: 25 | B8: 3221.535 | D8: 25 | E8: 3396.554 | G8: 25 | H8: 3204.301 | J8: 25 | K8: 3190.536 | M8: 25 | N8: 3031.085
A9: 30 | B9: 3222.111 | D9: 30 | E9: 3397.082 | G9: 30 | H9: 3202.629 | J9: 30 | K9: 3190.148 | M9: 30 | N9: 3032.597
A10: 35 | B10: 3223.004 | D10: 35 | E10: 3397.918 | G10: 35 | H10: 3201.624 | J10: 35 | K10: 3188.367 | M10: 35 | N10: 3033.784
A11: 40 | B11: 3224.328 | D11: 40 | E11: 3398.55 | G11: 40 | H11: 3200.39 | J11: 40 | K11: 3188.108 | M11: 40 | N11: 3034.738
A12: 45 | B12: 3225.676 | D12: 45 | E12: 3399.138 | G12: 45 | H12: 3199.252 | J12: 45 | K12: 3187.65 | M12: 45 | N12: 3035.947
A13: 50 | B13: 3225.607 | D13: 50 | E13: 3399.95 | G13: 50 | H13: 3199.04 | J13: 50 | K13: 3187.233 | M13: 50 | N13: 3036.497
A14: 55 | B14: 3225.707 | D14: 55 | E14: 3400.837 | G14: 55 | H14: 3199.398 | J14: 55 | K14: 3187.506 | M14: 55 | N14: 3037.162
... A50: 235 | B50: 3244.381 | D50: 235 | E50: 3420.621 | G50: 235 | H50: 3170.552 | J50: 235 | K50: 3174.965 | M50: 235 | N50: 3088.331
J51: 240 | K51: 3175.089
J52: 245 | K52: 3175.169
J53: 250 | K53: 3173.237
J54: 255 | K54: 3172.278
J55: 260 | K55: 3171.464
J56: 265 | K56: 3170.733
J57: 270 | K57: 3170.992
J58: 275 | K58: 3169.293
J59: 280 | K59: 3166.297
J60: 285 | K60: 3165.18
J61: 290 | K61: 3163.392
J62: 295 | K62: 3159.678
... J122: 595 | K122: 3107.404

Sheet GOL07_RST_ab_correct
A1: Name | B1: RA1 | C1: x | D1: z | E1: RST Topo | G1: Reflex W | I1: Pygimli | L1: x | M1: z | N1: RST Topo | P1: Reflex W | R1: Pygimli
W2: =I3 -> -7.5 | X2: 3192.405 | Y2: =W2 -> -7.5 | Z2: =X2 -> 3192.405
A3: OFF1 | C3: 992.5 | D3: =D4 -> 3192.405 | E3: =C3 -> 992.5 | F3: =ABS(D3-MAX(D:D))+0.01 -> 0.01 | G3: 0 | H3: 0 | I3: =C3-1000 -> -7.5 | J3: =J4 -> 3192.405 | W3: =E4-1000 -> 0 | X3: 3192.405 | Y3: =W3 -> 0 | Z3: =X3 -> 3192.405
A4: G1a | C4: 1000 | D4: 3192.405 | E4: =C4 -> 1000 | F4: =ABS(D4-MAX(D:D))+0.01 -> 0.01 | G4: =E4 -> 1000 | H4: =F4 -> 0.01 | I4: =C4-1000 -> 0 | J4: =D4 -> 3192.405 | W4: =E5-1000 -> 4.9555802 | X4: 3191.74 | Y4: =K54 -> 4.9555802 | Z4: =X4 -> 3191.74
A5: G2a | C5: =C4+$C$36 -> 1005 | D5: 3191.74 | E5: =E4+(SQRT((C5-C4)^2-(F5-F4)^2)) -> 1004.9556 | F5: =ABS(D5-MAX(D:D))+0.01 -> 0.675 | G5: =E5 -> 1004.9556 | H5: =F5 -> 0.675 | I5: =C5-1000 -> 5 | J5: =D5 -> 3191.74 | W5: =E6-1000 -> 9.9518152 | X5: 3191.546 | Y5: =K55 -> 9.9518152 | Z5: =X5 -> 3191.546
A6: G3a | C6: =C5+$C$36 -> 1010 | D6: 3191.546 | E6: =E5+(SQRT((C6-C5)^2-(F6-F5)^2)) -> 1009.9518 | F6: =ABS(D6-MAX(D:D))+0.01 -> 0.869 | G6: =E6 -> 1009.9518 | H6: =F6 -> 0.869 | I6: =C6-1000 -> 10 | J6: =D6 -> 3191.546 | W6: =E7-1000 -> 14.951814 | X6: 3191.55 | Y6: =K56 -> 14.951814 | Z6: =X6 -> 3191.55
A7: G4a | C7: =C6+$C$36 -> 1015 | D7: 3191.55 | E7: =E6+(SQRT((C7-C6)^2-(F7-F6)^2)) -> 1014.9518 | F7: =ABS(D7-MAX(D:D))+0.01 -> 0.865 | G7: =E7 -> 1014.9518 | H7: =F7 -> 0.865 | I7: =C7-1000 -> 15 | J7: =D7 -> 3191.55 | W7: =E8-1000 -> 19.664324 | X7: 3189.879 | Y7: =K57 -> 19.664324 | Z7: =X7 -> 3189.879
A8: G5a | C8: =C7+$C$36 -> 1020 | D8: 3189.879 | E8: =E7+(SQRT((C8-C7)^2-(F8-F7)^2)) -> 1019.6643 | F8: =ABS(D8-MAX(D:D))+0.01 -> 2.536 | G8: =E8 -> 1019.6643 | H8: =F8 -> 2.536 | I8: =C8-1000 -> 20 | J8: =D8 -> 3189.879 | W8: =E9-1000 -> 24.620972 | X8: 3190.536 | Y8: =K58 -> 24.620972 | Z8: =X8 -> 3190.536
A9: G6a | C9: =C8+$C$36 -> 1025 | D9: 3190.536 | E9: =E8+(SQRT((C9-C8)^2-(F9-F8)^2)) -> 1024.621 | F9: =ABS(D9-MAX(D:D))+0.01 -> 1.879 | G9: =E9 -> 1024.621 | H9: =F9 -> 1.879 | I9: =C9-1000 -> 25 | J9: =D9 -> 3190.536 | W9: =E10-1000 -> 29.605894 | X9: 3190.148 | Y9: =K59 -> 29.605894 | Z9: =X9 -> 3190.148
A10: G7a | C10: =C9+$C$36 -> 1030 | D10: 3190.148 | E10: =E9+(SQRT((C10-C9)^2-(F10-F9)^2)) -> 1029.6059 | F10: =ABS(D10-MAX(D:D))+0.01 -> 2.267 | G10: =E10 -> 1029.6059 | H10: =F10 -> 2.267 | I10: =C10-1000 -> 30 | J10: =D10 -> 3190.148 | W10: =E11-1000 -> 34.277943 | X10: 3188.367 | Y10: =K60 -> 34.277943 | Z10: =X10 -> 3188.367
A11: G8a | C11: =C10+$C$36 -> 1035 | D11: 3188.367 | E11: =E10+(SQRT((C11-C10)^2-(F11-F10)^2)) -> 1034.2779 | F11: =ABS(D11-MAX(D:D))+0.01 -> 4.048 | G11: =E11 -> 1034.2779 | H11: =F11 -> 4.048 | I11: =C11-1000 -> 35 | J11: =D11 -> 3188.367 | W11: =E12-1000 -> 39.271231 | X11: 3188.108 | Y11: =K61 -> 39.271231 | Z11: =X11 -> 3188.108
A12: G9a | C12: =C11+$C$36 -> 1040 | D12: 3188.108 | E12: =E11+(SQRT((C12-C11)^2-(F12-F11)^2)) -> 1039.2712 | F12: =ABS(D12-MAX(D:D))+0.01 -> 4.307 | G12: =E12 -> 1039.2712 | H12: =F12 -> 4.307 | I12: =C12-1000 -> 40 | J12: =D12 -> 3188.108 | W12: =E13-1000 -> 44.25021 | X12: 3187.65 | Y12: =K62 -> 44.25021 | Z12: =X12 -> 3187.65
A13: G10 | C13: =C12+$C$36 -> 1045 | D13: 3187.65 | E13: =E12+(SQRT((C13-C12)^2-(F13-F12)^2)) -> 1044.2502 | F13: =ABS(D13-MAX(D:D))+0.01 -> 4.765 | G13: =E13 -> 1044.2502 | H13: =F13 -> 4.765 | I13: =C13-1000 -> 45 | J13: =D13 -> 3187.65 | W13: =E14-1000 -> 49.232791 | X13: 3187.233 | Y13: =K63 -> 49.232791 | Z13: =X13 -> 3187.233
A14: G11 | C14: =C13+$C$36 -> 1050 | D14: 3187.233 | E14: =E13+(SQRT((C14-C13)^2-(F14-F13)^2)) -> 1049.2328 | F14: =ABS(D14-MAX(D:D))+0.01 -> 5.182 | G14: =E14 -> 1049.2328 | H14: =F14 -> 5.182 | I14: =C14-1000 -> 50 | J14: =D14 -> 3187.233 | W14: =E15-1000 -> 54.225332 | X14: 3187.506 | Y14: =K64 -> 54.225332 | Z14: =X14 -> 3187.506
A15: G12 | C15: =C14+$C$36 -> 1055 | D15: 3187.506 | E15: =E14+(SQRT((C15-C14)^2-(F15-F14)^2)) -> 1054.2253 | F15: =ABS(D15-MAX(D:D))+0.01 -> 4.909 | G15: =E15 -> 1054.2253 | H15: =F15 -> 4.909 | I15: =C15-1000 -> 55 | J15: =D15 -> 3187.506 | W15: =E16-1000 -> 59.225315 | X15: 3187.493 | Y15: =K65 -> 59.225315 | Z15: =X15 -> 3187.493
A16: G13 | C16: =C15+$C$36 -> 1060 | D16: 3187.493 | E16: =E15+(SQRT((C16-C15)^2-(F16-F15)^2)) -> 1059.2253 | F16: =ABS(D16-MAX(D:D))+0.01 -> 4.922 | G16: =E16 -> 1059.2253 | H16: =F16 -> 4.922 | I16: =C16-1000 -> 60 | J16: =D16 -> 3187.493 | W16: =E17-1000 -> 64.111229 | X16: 3186.431 | Y16: =K66 -> 64.111229 | Z16: =X16 -> 3186.431
... A19: G16 | C19: =C18+$C$36 -> 1075 | D19: 3184.053 | E19: =E18+(SQRT((C19-C18)^2-(F19-F18)^2)) -> 1073.8133 | F19: =ABS(D19-MAX(D:D))+0.01 -> 8.362 | G19: =E19 -> 1073.8133 | H19: =F19 -> 8.362 | I19: =C19-1000 -> 75 | J19: =D19 -> 3184.053 | W19: =E20-1000 -> 78.625083 | X19: 3182.694 | Y19: =K69 -> 78.625083 | Z19: =X19 -> 3182.694
A20: G17 | C20: =C19+$C$36 -> 1080 | D20: 3182.694 | E20: =E19+(SQRT((C20-C19)^2-(F20-F19)^2)) -> 1078.6251 | F20: =ABS(D20-MAX(D:D))+0.01 -> 9.721 | G20: =E20 -> 1078.6251 | H20: =F20 -> 9.721 | I20: =C20-1000 -> 80 | J20: =D20 -> 3182.694 | L20: OFF1 | M20: 3182.081 | N20: 1082.5 | O20: 0.1 | W20: =E21-1000 -> 83.587364 | X20: 3182.081 | Y20: =K70 -> 83.587364 | Z20: =X20 -> 3182.081
A21: G18 | C21: =C20+$C$36 -> 1085 | D21: 3182.081 | E21: =E20+(SQRT((C21-C20)^2-(F21-F20)^2)) -> 1083.5874 | F21: =ABS(D21-MAX(D:D))+0.01 -> 10.334 | G21: =E21 -> 1083.5874 | H21: =F21 -> 10.334 | I21: =C21-1000 -> 85 | J21: =D21 -> 3182.081 | L21: 1085 | M21: 3182.081 | N21: 1085 | O21: 0.01 | P21: 0 | Q21: 0 | R21: =N20-1000 -> 82.5 | S21: =M21 -> 3182.081 | W21: =E22-1000 -> 88.578772 | X21: 3181.788 | Y21: =K71 -> 88.578772 | Z21: =X21 -> 3181.788
A22: G19 | B22: G1b | C22: =C21+$C$36 -> 1090 | D22: 3181.788 | E22: =E21+(SQRT((C22-C21)^2-(F22-F21)^2)) -> 1088.5788 | F22: =ABS(D22-MAX(D:D))+0.01 -> 10.627 | G22: =E22 -> 1088.5788 | H22: =F22 -> 10.627 | I22: =C22-1000 -> 90 | J22: =D22 -> 3181.788 | L22: 1090 | M22: 3181.788 | N22: =N21+(SQRT((L22-L21)^2-(O22-O21)^2)) -> 1089.9914 | O22: =ABS(M22-MAX(M:M))+0.01 -> 0.303 | P22: =N22 -> 1089.9914 | Q22: =O22:O46 -> 0.303 | R22: =L22-1000 -> 90 | S22: =M22 -> 3181.788 | W22: =E23-1000 -> 93.578772 | X22: 3181.787 | Y22: =K72 -> 93.578772 | Z22: =X22 -> 3181.787
A23: G20 | B23: G2b | C23: =C22+$C$36 -> 1095 | D23: 3181.787 | E23: =E22+(SQRT((C23-C22)^2-(F23-F22)^2)) -> 1093.5788 | F23: =ABS(D23-MAX(D:D))+0.01 -> 10.628 | G23: =E23 -> 1093.5788 | H23: =F23 -> 10.628 | I23: =C23-1000 -> 95 | J23: =D23 -> 3181.787 | L23: =L22+$C$36 -> 1095 | M23: 3181.787 | N23: =N22+(SQRT((L23-L22)^2-(O23-O22)^2)) -> 1094.9914 | O23: =ABS(M23-MAX(M:M))+0.01 -> 0.304 | P23: =N23 -> 1094.9914 | Q23: =O23:O47 -> 0.304 | R23: =L23-1000 -> 95 | S23: =M23 -> 3181.787 | W23: =E24-1000 -> 96.828387 | X23: 3177.987 | Y23: =K73 -> 96.828387 | Z23: =X23 -> 3177.987
A24: G21 | B24: G3b | C24: =C23+$C$36 -> 1100 | D24: 3177.987 | E24: =E23+(SQRT((C24-C23)^2-(F24-F23)^2)) -> 1096.8284 | F24: =ABS(D24-MAX(D:D))+0.01 -> 14.428 | G24: =E24 -> 1096.8284 | H24: =F24 -> 14.428 | I24: =C24-1000 -> 100 | J24: =D24 -> 3177.987 | L24: =L23+$C$36 -> 1100 | M24: 3177.987 | N24: =N23+(SQRT((L24-L23)^2-(O24-O23)^2)) -> 1098.241 | O24: =ABS(M24-MAX(M:M))+0.01 -> 4.104 | P24: =N24 -> 1098.241 | Q24: =O24:O48 -> 4.104 | R24: =L24-1000 -> 100 | S24: =M24 -> 3177.987 | W24: =E25-1000 -> 101.82193 | X24: 3178.241 | Y24: =K74 -> 101.82193 | Z24: =X24 -> 3178.241
A25: G22 | B25: G4b | C25: =C24+$C$36 -> 1105 | D25: 3178.241 | E25: =E24+(SQRT((C25-C24)^2-(F25-F24)^2)) -> 1101.8219 | F25: =ABS(D25-MAX(D:D))+0.01 -> 14.174 | G25: =E25 -> 1101.8219 | H25: =F25 -> 14.174 | I25: =C25-1000 -> 105 | J25: =D25 -> 3178.241 | L25: =L24+$C$36 -> 1105 | M25: 3178.241 | N25: =N24+(SQRT((L25-L24)^2-(O25-O24)^2)) -> 1103.2346 | O25: =ABS(M25-MAX(M:M))+0.01 -> 3.85 | P25: =N25 -> 1103.2346 | Q25: =O25:O49 -> 3.85 | R25: =L25-1000 -> 105 | S25: =M25 -> 3178.241 | W25: =E26-1000 -> 106.77548 | X25: 3177.561 | Y25: =K75 -> 106.77548 | Z25: =X25 -> 3177.561
A26: G23 | B26: G5b | C26: =C25+$C$36 -> 1110 | D26: 3177.561 | E26: =E25+(SQRT((C26-C25)^2-(F26-F25)^2)) -> 1106.7755 | F26: =ABS(D26-MAX(D:D))+0.01 -> 14.854 | G26: =E26 -> 1106.7755 | H26: =F26 -> 14.854 | I26: =C26-1000 -> 110 | J26: =D26 -> 3177.561 | L26: =L25+$C$36 -> 1110 | M26: 3177.561 | N26: =N25+(SQRT((L26-L25)^2-(O26-O25)^2)) -> 1108.1881 | O26: =ABS(M26-MAX(M:M))+0.01 -> 4.53 | P26: =N26 -> 1108.1881 | Q26: =O26:O50 -> 4.53 | R26: =L26-1000 -> 110 | S26: =M26 -> 3177.561 | W26: =E27-1000 -> 111.76855 | X26: 3177.298 | Y26: =K76 -> 111.76855 | Z26: =X26 -> 3177.298
A27: G24a | B27: G6 | C27: =C26+$C$36 -> 1115 | D27: 3177.298 | E27: =E26+(SQRT((C27-C26)^2-(F27-F26)^2)) -> 1111.7686 | F27: =ABS(D27-MAX(D:D))+0.01 -> 15.117 | G27: =E27 -> 1111.7686 | H27: =F27 -> 15.117 | I27: =C27-1000 -> 115 | J27: =D27 -> 3177.298 | L27: =L26+$C$36 -> 1115 | M27: 3177.298 | N27: =N26+(SQRT((L27-L26)^2-(O27-O26)^2)) -> 1113.1812 | O27: =ABS(M27-MAX(M:M))+0.01 -> 4.793 | P27: =N27 -> 1113.1812 | Q27: =O27:O51 -> 4.793 | R27: =L27-1000 -> 115 | S27: =M27 -> 3177.298 | W27: =E28-1000 -> 119.26855 | X27: 3176.399 | Y27: =K77 -> 116.68707 | Z27: =X27 -> 3176.399
A28: OFF3a | B28: G7 | C28: =1122.5 -> 1122.5 | D28: =D27 -> 3177.298 | E28: =E27+(SQRT((C28-C27)^2-(F28-F27)^2)) -> 1119.2686 | F28: =ABS(D28-MAX(D:D))+0.01 -> 15.117 | I28: =C28-1000 -> 122.5 | J28: =J27-0.5 -> 3176.798 | L28: =L27+$C$36 -> 1120 | M28: 3176.399 | N28: =N27+(SQRT((L28-L27)^2-(O28-O27)^2)) -> 1118.0997 | O28: =ABS(M28-MAX(M:M))+0.01 -> 5.692 | P28: =N28 -> 1118.0997 | Q28: =O28:O52 -> 5.692 | R28: =L28-1000 -> 120 | S28: =M28 -> 3176.399 | W28: =N29-1000 -> 123.08793 | X28: 3176.56 | Y28: =K78 -> 121.67529 | Z28: =X28 -> 3176.56
B29: G8 | L29: =L28+$C$36 -> 1125 | M29: 3176.056 | N29: =N28+(SQRT((L29-L28)^2-(O29-O28)^2)) -> 1123.0879 | O29: =ABS(M29-MAX(M:M))+0.01 -> 6.035 | P29: =N29 -> 1123.0879 | Q29: =O29:O52 -> 6.035 | R29: =L29-1000 -> 125 | S29: =M29 -> 3176.056 | W29: =N30-1000 -> 128.06541 | X29: 3175.582 | Y29: =K79 -> 126.65277 | Z29: =X29 -> 3175.582
B30: G9 | L30: =L29+$C$36 -> 1130 | M30: 3175.582 | N30: =N29+(SQRT((L30-L29)^2-(O30-O29)^2)) -> 1128.0654 | O30: =ABS(M30-MAX(M:M))+0.01 -> 6.509 | P30: =N30 -> 1128.0654 | Q30: =O30:O52 -> 6.509 | R30: =L30-1000 -> 130 | S30: =M30 -> 3175.582 | W30: =N31-1000 -> 133.04807 | X30: 3175.166 | Y30: =K80 -> 131.63544 | Z30: =X30 -> 3175.166
B31: G10 | L31: =L30+$C$36 -> 1135 | M31: 3175.166 | N31: =N30+(SQRT((L31-L30)^2-(O31-O30)^2)) -> 1133.0481 | O31: =ABS(M31-MAX(M:M))+0.01 -> 6.925 | P31: =N31 -> 1133.0481 | Q31: =O31:O53 -> 6.925 | R31: =L31-1000 -> 135 | S31: =M31 -> 3175.166 | W31: =N32-1000 -> 137.53953 | X31: 3172.969 | Y31: =K81 -> 136.12689 | Z31: =X31 -> 3172.969
B32: G11 | L32: =L31+$C$36 -> 1140 | M32: 3172.969 | N32: =N31+(SQRT((L32-L31)^2-(O32-O31)^2)) -> 1137.5395 | O32: =ABS(M32-MAX(M:M))+0.01 -> 9.122 | P32: =N32 -> 1137.5395 | Q32: =O32:O54 -> 9.122 | R32: =L32-1000 -> 140 | S32: =M32 -> 3172.969 | W32: =N33-1000 -> 142.53697 | X32: 3173.129 | Y32: =K82 -> 141.12433 | Z32: =X32 -> 3173.129
B33: G12 | L33: =L32+$C$36 -> 1145 | M33: 3173.129 | N33: =N32+(SQRT((L33-L32)^2-(O33-O32)^2)) -> 1142.537 | O33: =ABS(M33-MAX(M:M))+0.01 -> 8.962 | P33: =N33 -> 1142.537 | Q33: =O33:O55 -> 8.962 | R33: =L33-1000 -> 145 | S33: =M33 -> 3173.129 | W33: =N34-1000 -> 147.4748 | X33: 3173.915 | Y33: =K83 -> 146.06217 | Z33: =X33 -> 3173.915
B34: G13 | L34: =L33+$C$36 -> 1150 | M34: 3173.915 | N34: =N33+(SQRT((L34-L33)^2-(O34-O33)^2)) -> 1147.4748 | O34: =ABS(M34-MAX(M:M))+0.01 -> 8.176 | P34: =N34 -> 1147.4748 | Q34: =O34:O56 -> 8.176 | R34: =L34-1000 -> 150 | S34: =M34 -> 3173.915 | W34: =N35-1000 -> 152.44278 | X34: 3173.35 | Y34: =K84 -> 151.03014 | Z34: =X34 -> 3173.35
B35: G14 | L35: =L34+$C$36 -> 1155 | M35: 3173.35 | N35: =N34+(SQRT((L35-L34)^2-(O35-O34)^2)) -> 1152.4428 | O35: =ABS(M35-MAX(M:M))+0.01 -> 8.741 | P35: =N35 -> 1152.4428 | Q35: =O35:O57 -> 8.741 | R35: =L35-1000 -> 155 | S35: =M35 -> 3173.35 | W35: =N36-1000 -> 157.32519 | X35: 3172.272 | Y35: =K85 -> 155.91255 | Z35: =X35 -> 3172.272
B36: G15 | C36: 5 | L36: =L35+$C$36 -> 1160 | M36: 3172.272 | N36: =N35+(SQRT((L36-L35)^2-(O36-O35)^2)) -> 1157.3252 | O36: =ABS(M36-MAX(M:M))+0.01 -> 9.819 | P36: =N36 -> 1157.3252 | Q36: =O36:O58 -> 9.819 | R36: =L36-1000 -> 160 | S36: =M36 -> 3172.272 | W36: =N37-1000 -> 161.87292 | X36: 3174.35 | Y36: =K86 -> 160.46029 | Z36: =X36 -> 3174.35
B37: G16 | L37: =L36+$C$36 -> 1165 | M37: 3174.35 | N37: =N36+(SQRT((L37-L36)^2-(O37-O36)^2)) -> 1161.8729 | O37: =ABS(M37-MAX(M:M))+0.01 -> 7.741 | P37: =N37 -> 1161.8729 | Q37: =O37:O59 -> 7.741 | R37: =L37-1000 -> 165 | S37: =M37 -> 3174.35 | W37: =N38-1000 -> 166.75467 | X37: 3173.269 | Y37: =K87 -> 165.34203 | Z37: =X37 -> 3173.269
B38: G17 | L38: =L37+$C$36 -> 1170 | M38: 3173.269 | N38: =N37+(SQRT((L38-L37)^2-(O38-O37)^2)) -> 1166.7547 | O38: =ABS(M38-MAX(M:M))+0.01 -> 8.822 | P38: =N38 -> 1166.7547 | Q38: =O38:O60 -> 8.822 | R38: =L38-1000 -> 170 | S38: =M38 -> 3173.269 | W38: =N39-1000 -> 171.70571 | X38: 3173.967 | Y38: =K88 -> 170.29307 | Z38: =X38 -> 3173.967
B39: G18 | L39: =L38+$C$36 -> 1175 | M39: 3173.967 | N39: =N38+(SQRT((L39-L38)^2-(O39-O38)^2)) -> 1171.7057 | O39: =ABS(M39-MAX(M:M))+0.01 -> 8.124 | P39: =N39 -> 1171.7057 | Q39: =O39:O61 -> 8.124 | R39: =L39-1000 -> 175 | S39: =M39 -> 3173.967 | W39: =N40-1000 -> 176.28127 | X39: 3171.951 | Y39: =K89 -> 174.86863 | Z39: =X39 -> 3171.951
